Workbook

Sheet Idle-Normal
A1: Fator | B1: Cont | C1: Valor | D1: Dgts | M1: PRINCIPAL
A2: - | B2: 1 | C2: 1 | D2: =LEN(TEXT(C2,0)) -> 1 | F2: Fator Mult. | G2: =ROUND(G38*G39,1) -> 59
A3: k | B3: =B2+1 -> 2 | C3: =C2*1000 -> 1000 | D3: =LEN(TEXT(C3,0)) -> 4
A4: m | B4: =B3+1 -> 3 | C4: =C3*1000 -> 1000000 | D4: =LEN(TEXT(C4,0)) -> 7 | F4: Atual | G4: =(SUM(AK7:AK11,AK17:AK21,AK27:AK31,AK37:AK41,AK47:AK51,AK57:AK61,AK67:AK71,AK77:AK81)) -> 151 | I4: =G4/G6 -> 0.88823529 | AJ4: Dinheiro
A5: b | B5: =B4+1 -> 4 | C5: =C4*1000 -> 1000000000 | D5: =LEN(TEXT(C5,0)) -> 10 | M5: Dinheiro | AJ5: Mina | AK5: Prestigo Atual | AL5: GAP | AM5: Verificação | AN5: Valor OffLine | AT5: Próximo Prestigio
A6: t | B6: =B5+1 -> 5 | C6: =C5*1000 -> 1000000000000 | D6: =LEN(TEXT(C6,0)) -> 13 | F6: Meta | G6: 170 | I6: =(6*5)*8 -> 240 | M6: Mina | N6: Armazem | P6: Armazem Valor | Q6: Elevador | S6: Elevador Valor | T6: Extração | V6: Extração Valor | W6: Ordem | Y6: Valor | Z6: ColsAjust | AA6: ColFator | AB6: AjsuteCol | AC6: Coluna | AD6: Linha | AE6: Valor Mínimo | AH6: Verificação | AN6: Ordem | AP6: Valor | AQ6: Multip. | AR6: Repre. | AT6: Ordem | AU6: Valor Real | AV6: Valor | AW6: Multip.
A7: aa | B7: =B6+1 -> 6 | C7: =C6*1000 -> 1e+15 | D7: =LEN(TEXT(C7,0)) -> 16 | M7: Carvão | N7: 427 | O7: bb | P7: =N7*(VLOOKUP(O7,tab_fator[],3,0)) -> 4.27e+98 | Q7: 446 | R7: bb | S7: =Q7*(VLOOKUP(R7,tab_fator[],3,0)) -> 4.46e+98 | T7: 403 | U7: bb | V7: =T7*(VLOOKUP(U7,tab_fator[],3,0)) -> 4.03e+98 | W7: =_xlfn.RANK.EQ(V7,$V7:$V11) -> 2 | Y7: =MIN(V7,S7,P7) -> 4.03e+98 | Z7: =MATCH(Y7,M7:V7,0) -> 10 | AA7: =COLUMN($L$1) -> 12 | AB7: 2 | AC7: =Z7+AA7-AB7 -> 20 | AD7: =ROW(M7) -> 7 | AE7: {=INDIRECT(ADDRESS(AD7,AC7,1,1))} -> 403 | AF7: {=INDIRECT(ADDRESS(AD7,AC7+1,1,1))} -> bb | AH7: =IF(AND(V7<S7,V7<P7),"Equilibrado","Ver") -> Equilibrado | AJ7: Carvão | AK7: 6 | AL7: =VLOOKUP(I10,tab_fator[],2,0)-VLOOKUP(AQ7,tab_fator[],2,0) -> 2 | AM7: =IF(AN7+AT7=6,"Equilibrado","Ver") -> Ver | AN7: =_xlfn.RANK.EQ(AO7,AO7:AO11) -> 2 | AO7: =AP7*(VLOOKUP(AQ7,tab_fator[],3,0)) -> 2.38e+99 | AP7: ='Transformação-Normal'!Q7 -> 2.38 | AQ7: ='Transformação-Normal'!R7 -> bc | AR7: =AO7/SUM(AO7:AO11) -> 0.20995801 | AS7: =(AP7*VLOOKUP(AQ7,tab_fator[],3,0))+ (AP8*VLOOKUP(AQ8,tab_fator[],3,0))+ (AP9*VLOOKUP(AQ9,tab_fator[],3,0))+ (AP10*VLOOKUP(AQ10,tab_fator[],3,0))+ (AP11*VLOOKUP(AQ11,tab_fator[],3,0)) -> 1.13356e+100 | AT7: =_xlfn.RANK.EQ(AU7,$AU$7:$AU$11,1) -> 5 | AU7: =AV7*(VLOOKUP(AW7,tab_fator[],3,0)) -> 7.6705e+112 | AV7: 76.705 | AW7: bg | AX7: *Poço 31
A8: ab | B8: =B7+1 -> 7 | C8: =C7*1000 -> 1e+18 | D8: =LEN(TEXT(C8,0)) -> 19 | F8: PRINCIPAL | M8: Ouro | N8: 445 | O8: bb | P8: =N8*(VLOOKUP(O8,tab_fator[],3,0)) -> 4.45e+98 | Q8: 398 | R8: bb | S8: =Q8*(VLOOKUP(R8,tab_fator[],3,0)) -> 3.98e+98 | T8: 344 | U8: bb | V8: =T8*(VLOOKUP(U8,tab_fator[],3,0)) -> 3.44e+98 | W8: =_xlfn.RANK.EQ(V8,$V$7:$V$11) -> 3 | Y8: =MIN(V8,S8,P8) -> 3.44e+98 | Z8: =MATCH(Y8,M8:V8,0) -> 10 | AA8: =COLUMN($L$1) -> 12 | AB8: 2 | AC8: =Z8+AA8-AB8 -> 20 | AD8: =ROW(X8) -> 8 | AE8: {=INDIRECT(ADDRESS(AD8,AC8,1,1))} -> 344 | AF8: {=INDIRECT(ADDRESS(AD8,AC8+1,1,1))} -> bb | AH8: =IF(AND(V8<S8,V8<P8),"Equilibrado","Ver") -> Equilibrado | AJ8: Ouro | AK8: 6 | AL8: =VLOOKUP(I10,tab_fator[],2,0)-VLOOKUP(AQ8,tab_fator[],2,0) -> 2 | AM8: =IF(AN8+AT8=6,"Equilibrado","Ver") -> Equilibrado | AN8: =_xlfn.RANK.EQ(AO8,AO7:AO11) -> 3 | AO8: =AP8*(VLOOKUP(AQ8,tab_fator[],3,0)) -> 2.03e+99 | AP8: ='Transformação-Normal'!Q8 -> 2.03 | AQ8: ='Transformação-Normal'!R8 -> bc | AR8: =AO8/SUM(AO7:AO11) -> 0.17908183 | AS8: =_xlfn.XLOOKUP((LEN(TEXT(AS7,0))),tab_fator[Dgts],tab_fator[Fator],"errro",-1,1) -> bc | AT8: =_xlfn.RANK.EQ(AU8,$AU$7:$AU$11,1) -> 3 | AU8: =AV8*(VLOOKUP(AW8,tab_fator[],3,0)) -> 7.6704e+112 | AV8: 76.704 | AW8: bg | AX8: *Poço 31
A9: ac | B9: =B8+1 -> 8 | C9: =C8*1000 -> 1e+21 | D9: =LEN(TEXT(C9,0)) -> 22 | F9: Ilha | G9: Próximo | H9: Valor | J9: Falta Horas | K9: Falta Letras | M9: Rubi | N9: 1.31 | O9: bc | P9: =N9*(VLOOKUP(O9,tab_fator[],3,0)) -> 1.31e+99 | Q9: 1.36 | R9: bc | S9: =Q9*(VLOOKUP(R9,tab_fator[],3,0)) -> 1.36e+99 | T9: 1.16 | U9: bc | V9: =T9*(VLOOKUP(U9,tab_fator[],3,0)) -> 1.16e+99 | W9: =_xlfn.RANK.EQ(V9,$V$7:$V$11) -> 1 | Y9: =MIN(V9,S9,P9) -> 1.16e+99 | Z9: =MATCH(Y9,M9:V9,0) -> 10 | AA9: =COLUMN($L$1) -> 12 | AB9: 2 | AC9: =Z9+AA9-AB9 -> 20 | AD9: =ROW(X9) -> 9 | AE9: {=INDIRECT(ADDRESS(AD9,AC9,1,1))} -> 1.16 | AF9: {=INDIRECT(ADDRESS(AD9,AC9+1,1,1))} -> bc | AH9: =IF(AND(V9<S9,V9<P9),"Equilibrado","Ver") -> Equilibrado | AJ9: Rubi | AK9: 6 | AL9: =VLOOKUP(I10,tab_fator[],2,0)-VLOOKUP(AQ9,tab_fator[],2,0) -> 2 | AM9: =IF(AN9+AT9=6,"Equilibrado","Ver") -> Ver | AN9: =_xlfn.RANK.EQ(AO9,AO7:AO11) -> 1 | AO9: =AP9*(VLOOKUP(AQ9,tab_fator[],3,0)) -> 6.84e+99 | AP9: ='Transformação-Normal'!Q9 -> 6.84 | AQ9: ='Transformação-Normal'!R9 -> bc | AR9: =AO9/SUM(AO7:AO11) -> 0.60340873 | AS9: =VLOOKUP(AS8,tab_fator[],3,0) -> 1e+99 | AT9: =_xlfn.RANK.EQ(AU9,$AU$7:$AU$11,1) -> 2 | AU9: =AV9*(VLOOKUP(AW9,tab_fator[],3,0)) -> 7.6703e+112 | AV9: 76.703 | AW9: bg | AX9: *Poço 31
A10: ad | B10: =B9+1 -> 9 | C10: =C9*1000 -> 1e+24 | D10: =LEN(TEXT(C10,0)) -> 25 | F10: Principal | G10: =_xlfn.XLOOKUP(1,AT7:AT11,AJ7:AJ11,"Erro",0,1) -> Esmeralda | H10: =VLOOKUP(G10,$AJ$7:$AW$82,13,0) -> 7.71 | I10: =VLOOKUP(G10,$AJ$7:$AW$82,14,0) -> be | J10: =_xlfn.CONCAT(INT(((((VLOOKUP(1,$AT$7:$AW$11,3,0)*(VLOOKUP(((VLOOKUP((VLOOKUP(1,$AT$7:$AW$11,4,0)),tab_fator[],2,0))-(VLOOKUP(AQ12,tab_fator[],2,0))+1),tab_fator[[#All],[Cont]:[Valor]],2,0)))/$AP$12)/60/60/24)))," Dias e ",TEXT(((((VLOOKUP(1,$AT$7:$AW$11,3,0)*(VLOOKUP(((VLOOKUP((VLOOKUP(1,$AT$7:$AW$11,4,0)),tab_fator[],2,0))-(VLOOKUP(AQ12,tab_fator[],2,0))+1),tab_fator[[#All],[Cont]:[Valor]],2,0)))/$AP$12)/60/60/24)),"hh:mm")) -> 7 Dias e 21:31 | K10: =(VLOOKUP(AQ12,tab_fator[],2,0)-(VLOOKUP(VLOOKUP(1,$AT$7:$AW$11,4,0),tab_fator[],2,0)))*-1 -> 2 | M10: Diamante | N10: 220 | O10: at | P10: =N10*(VLOOKUP(O10,tab_fator[],3,0)) -> 2.2e+74 | Q10: 252 | R10: at | S10: =Q10*(VLOOKUP(R10,tab_fator[],3,0)) -> 2.52e+74 | T10: 42.9 | U10: at | V10: =T10*(VLOOKUP(U10,tab_fator[],3,0)) -> 4.29e+73 | W10: =_xlfn.RANK.EQ(V10,$V$7:$V$11) -> 5 | Y10: =MIN(V10,S10,P10) -> 4.29e+73 | Z10: =MATCH(Y10,M10:V10,0) -> 10 | AA10: =COLUMN($L$1) -> 12 | AB10: 2 | AC10: =Z10+AA10-AB10 -> 20 | AD10: =ROW(X10) -> 10 | AE10: {=INDIRECT(ADDRESS(AD10,AC10,1,1))} -> 42.9 | AF10: {=INDIRECT(ADDRESS(AD10,AC10+1,1,1))} -> at | AH10: =IF(AND(V10<S10,V10<P10),"Equilibrado","Ver") -> Equilibrado | AJ10: Diamante | AK10: 6 | AL10: =VLOOKUP(I10,tab_fator[],2,0)-VLOOKUP(AQ10,tab_fator[],2,0) -> 11 | AM10: =IF(AN10+AT10=6,"Equilibrado","Ver") -> Ver | AN10: =_xlfn.RANK.EQ(AO10,AO7:AO11) -> 5 | AO10: =AP10*(VLOOKUP(AQ10,tab_fator[],3,0)) -> 2.53e+74 | AP10: ='Transformação-Normal'!Q10 -> 253 | AQ10: ='Transformação-Normal'!R10 -> at | AR10: =AO10/SUM(AO7:AO11) -> 2.2319066e-26 | AT10: =_xlfn.RANK.EQ(AU10,$AU$7:$AU$11,1) -> 3 | AU10: =AV10*(VLOOKUP(AW10,tab_fator[],3,0)) -> 7.6704e+112 | AV10: 76.704 | AW10: bg | AX10: *Poço 31
A11: ae | B11: =B10+1 -> 10 | C11: =C10*1000 -> 1e+27 | D11: =LEN(TEXT(C11,0)) -> 28 | F11: Gelo | G11: =_xlfn.XLOOKUP(1,AT17:AT21,AJ17:AJ21,"Erro",0,1) -> Seletina | H11: =VLOOKUP(G11,$AJ$7:$AW$82,13,0) -> 1.44 | I11: =VLOOKUP(G11,$AJ$7:$AW$82,14,0) -> bd | J11: =_xlfn.CONCAT(INT(((((VLOOKUP(1,$AT$17:$AW$21,3,0)*(VLOOKUP(((VLOOKUP((VLOOKUP(1,$AT$17:$AW$21,4,0)),tab_fator[],2,0))-(VLOOKUP(AQ22,tab_fator[],2,0))+1),tab_fator[[#All],[Cont]:[Valor]],2,0)))/AP22)/60/60/24)))," Dias e ",TEXT(((((VLOOKUP(1,$AT$17:$AW$21,3,0)*(VLOOKUP(((VLOOKUP((VLOOKUP(1,$AT$17:$AW$21,4,0)),tab_fator[],2,0))-(VLOOKUP(AQ22,tab_fator[],2,0))+1),tab_fator[[#All],[Cont]:[Valor]],2,0)))/AP22)/60/60/24)),"hh:mm")) -> 102 Dias e 21:08 | K11: =(VLOOKUP(AQ22,tab_fator[],2,0)-(VLOOKUP(VLOOKUP(1,$AT$17:$AW$21,4,0),tab_fator[],2,0)))*-1 -> 3 | M11: Esmeralda | N11: 31.3 | O11: bb | P11: =N11*(VLOOKUP(O11,tab_fator[],3,0)) -> 3.13e+97 | Q11: 15.1 | R11: bb | S11: =Q11*(VLOOKUP(R11,tab_fator[],3,0)) -> 1.51e+97 | T11: 14.5 | U11: bb | V11: =T11*(VLOOKUP(U11,tab_fator[],3,0)) -> 1.45e+97 | W11: =_xlfn.RANK.EQ(V11,$V$7:$V$11) -> 4 | Y11: =MIN(V11,S11,P11) -> 1.45e+97 | Z11: =MATCH(Y11,M11:V11,0) -> 10 | AA11: =COLUMN($L$1) -> 12 | AB11: 2 | AC11: =Z11+AA11-AB11 -> 20 | AD11: =ROW(X11) -> 11 | AE11: {=INDIRECT(ADDRESS(AD11,AC11,1,1))} -> 14.5 | AF11: {=INDIRECT(ADDRESS(AD11,AC11+1,1,1))} -> bb | AH11: =IF(AND(V11<S11,V11<P11),"Equilibrado","Ver") -> Equilibrado | AJ11: Esmeralda | AK11: 5 | AL11: =VLOOKUP(I10,tab_fator[],2,0)-VLOOKUP(AQ11,tab_fator[],2,0) -> 3 | AM11: =IF(AN11+AT11=6,"Equilibrado","Ver") -> Ver | AN11: =_xlfn.RANK.EQ(AO11,AO7:AO11) -> 4 | AO11: =AP11*(VLOOKUP(AQ11,tab_fator[],3,0)) -> 8.56e+97 | AP11: ='Transformação-Normal'!Q11 -> 85.6 | AQ11: ='Transformação-Normal'!R11 -> bb | AR11: =AO11/SUM(AO7:AO11) -> 0.0075514309 | AT11: =_xlfn.RANK.EQ(AU11,$AU$7:$AU$11,1) -> 1 | AU11: =AV11*(VLOOKUP(AW11,tab_fator[],3,0)) -> 7.71e+105 | AV11: 7.71 | AW11: be
A12: af | B12: =B11+1 -> 11 | C12: =C11*1000 -> 1e+30 | D12: =LEN(TEXT(C12,0)) -> 31 | F12: Fogo | G12: =_xlfn.XLOOKUP(1,AT27:AT31,AJ27:AJ31,"Erro",0,1) -> Ambar | H12: =VLOOKUP(G12,$AJ$7:$AW$82,13,0) -> 2.81 | I12: =VLOOKUP(G12,$AJ$7:$AW$82,14,0) -> bc | J12: =_xlfn.CONCAT(INT(((((VLOOKUP(1,$AT$27:$AW$31,3,0)*(VLOOKUP(((VLOOKUP((VLOOKUP(1,$AT$27:$AW$31,4,0)),tab_fator[],2,0))-(VLOOKUP(AQ32,tab_fator[],2,0))+1),tab_fator[[#All],[Cont]:[Valor]],2,0)))/AP32)/60/60/24)))," Dias e ",TEXT(((((VLOOKUP(1,$AT$27:$AW$31,3,0)*(VLOOKUP(((VLOOKUP((VLOOKUP(1,$AT$27:$AW$31,4,0)),tab_fator[],2,0))-(VLOOKUP(AQ32,tab_fator[],2,0))+1),tab_fator[[#All],[Cont]:[Valor]],2,0)))/AP32)/60/60/24)),"hh:mm")) -> 256 Dias e 02:06 | K12: =(VLOOKUP(AQ32,tab_fator[],2,0)-(VLOOKUP(VLOOKUP(1,$AT$27:$AW$31,4,0),tab_fator[],2,0)))*-1 -> 3 | AJ12: Total | AK12: =CONCATENATE(SUM(AK7:AK11)," / ",6*5) -> 29 / 30 | AP12: =IF(AS7/AS9<10,(TEXT(AS7/AS9,"#,##")),IF(AS7/AS9<100,TEXT(AS7/AS9,"##,#"),TEXT(AS7/AS9,"###"))) -> 11,3 | AQ12: =AS8 -> bc | AT12: =IF((AP12*VLOOKUP(AQ12,tab_fator[],3,0))>(_xlfn.XLOOKUP(1,AT7:AT11,AV7:AV11,"",0,1)*VLOOKUP((_xlfn.XLOOKUP(1,AT7:AT11,AW7:AW11,"",0,1)),tab_fator[],3,0)),"Pronto","Esperar") -> Esperar
A13: ag | B13: =B12+1 -> 12 | C13: =C12*1000 -> 1e+33 | D13: =LEN(TEXT(C13,0)) -> 34 | F13: Aurora | G13: =_xlfn.XLOOKUP(1,AT37:AT41,AJ37:AJ41,"Erro",0,1) -> Realgar | H13: =VLOOKUP(G13,$AJ$7:$AW$82,13,0) -> 15.1 | I13: =VLOOKUP(G13,$AJ$7:$AW$82,14,0) -> ay | J13: =_xlfn.CONCAT(INT(((((VLOOKUP(1,$AT$37:$AW$41,3,0)*(VLOOKUP(((VLOOKUP((VLOOKUP(1,$AT$37:$AW$41,4,0)),tab_fator[],2,0))-(VLOOKUP(AQ42,tab_fator[],2,0))+1),tab_fator[[#All],[Cont]:[Valor]],2,0)))/AP42)/60/60/24)))," Dias e ",TEXT(((((VLOOKUP(1,$AT$37:$AW$41,3,0)*(VLOOKUP(((VLOOKUP((VLOOKUP(1,$AT$37:$AW$41,4,0)),tab_fator[],2,0))-(VLOOKUP(AQ42,tab_fator[],2,0))+1),tab_fator[[#All],[Cont]:[Valor]],2,0)))/AP42)/60/60/24)),"hh:mm")) -> 12 Dias e 07:23 | K13: =(VLOOKUP(AQ42,tab_fator[],2,0)-(VLOOKUP(VLOOKUP(1,$AT$37:$AW$41,4,0),tab_fator[],2,0)))*-1 -> 2
A14: ah | B14: =B13+1 -> 13 | C14: =C13*1000 -> 1e+36 | D14: =LEN(TEXT(C14,0)) -> 37 | F14: Crepúsculo | G14: =_xlfn.XLOOKUP(1,AT47:AT51,AJ47:AJ51,"Erro",0,1) -> Fluorita | H14: =VLOOKUP(G14,$AJ$7:$AW$82,13,0) -> 11.9 | I14: =VLOOKUP(G14,$AJ$7:$AW$82,14,0) -> ax | J14: =_xlfn.CONCAT(INT(((((VLOOKUP(1,$AT$47:$AW$51,3,0)*(VLOOKUP(((VLOOKUP((VLOOKUP(1,$AT$47:$AW$51,4,0)),tab_fator[],2,0))-(VLOOKUP(AQ52,tab_fator[],2,0))+1),tab_fator[[#All],[Cont]:[Valor]],2,0)))/AP52)/60/60/24)))," Dias e ",TEXT(((((VLOOKUP(1,$AT$47:$AW$51,3,0)*(VLOOKUP(((VLOOKUP((VLOOKUP(1,$AT$47:$AW$51,4,0)),tab_fator[],2,0))-(VLOOKUP(AQ52,tab_fator[],2,0))+1),tab_fator[[#All],[Cont]:[Valor]],2,0)))/AP52)/60/60/24)),"hh:mm")) -> 62 Dias e 07:43 | K14: =(VLOOKUP(AQ52,tab_fator[],2,0)-(VLOOKUP(VLOOKUP(1,$AT$47:$AW$51,4,0),tab_fator[],2,0)))*-1 -> 2 | AJ14: Dinheiro de Gelo
A15: ai | B15: =B14+1 -> 14 | C15: =C14*1000 -> 1e+39 | D15: =LEN(TEXT(C15,0)) -> 40 | F15: Antigo | G15: =_xlfn.XLOOKUP(1,AT57:AT61,AJ57:AJ61,"Erro",0,1) -> Pérola | H15: =VLOOKUP(G15,$AJ$7:$AW$82,13,0) -> 432 | I15: =VLOOKUP(G15,$AJ$7:$AW$82,14,0) -> aw | J15: =_xlfn.CONCAT(INT(((((VLOOKUP(1,$AT$57:$AW$61,3,0)*(VLOOKUP(((VLOOKUP((VLOOKUP(1,$AT$57:$AW$61,4,0)),tab_fator[],2,0))-(VLOOKUP(AQ62,tab_fator[],2,0))+1),tab_fator[[#All],[Cont]:[Valor]],2,0)))/AP62)/60/60/24)))," Dias e ",TEXT(((((VLOOKUP(1,$AT$57:$AW$61,3,0)*(VLOOKUP(((VLOOKUP((VLOOKUP(1,$AT$57:$AW$61,4,0)),tab_fator[],2,0))-(VLOOKUP(AQ62,tab_fator[],2,0))+1),tab_fator[[#All],[Cont]:[Valor]],2,0)))/AP62)/60/60/24)),"hh:mm")) -> 54 Dias e 12:36 | K15: =(VLOOKUP(AQ62,tab_fator[],2,0)-(VLOOKUP(VLOOKUP(1,$AT$57:$AW$61,4,0),tab_fator[],2,0)))*-1 -> 2 | M15: Dinheiro de Gelo | AJ15: Mina | AK15: Prestigo | AL15: GAP | AM15: Verificação | AN15: Valor OffLine | AT15: Próximo Prestigio
A16: aj | B16: =B15+1 -> 15 | C16: =C15*1000 -> 1e+42 | D16: =LEN(TEXT(C16,0)) -> 43 | F16: Deserto | G16: =_xlfn.XLOOKUP(1,AT67:AT71,AJ67:AJ71,"Erro",0,1) -> Crisoberílio | H16: =VLOOKUP(G16,$AJ$7:$AW$82,13,0) -> 55.1 | I16: =VLOOKUP(G16,$AJ$7:$AW$82,14,0) -> ax | J16: =_xlfn.CONCAT(INT(((((VLOOKUP(1,$AT$67:$AW$71,3,0)*(VLOOKUP(((VLOOKUP((VLOOKUP(1,$AT$67:$AW$71,4,0)),tab_fator[],2,0))-(VLOOKUP(AQ72,tab_fator[],2,0))+1),tab_fator[[#All],[Cont]:[Valor]],2,0)))/AP72)/60/60/24)))," Dias e ",TEXT(((((VLOOKUP(1,$AT$67:$AW$71,3,0)*(VLOOKUP(((VLOOKUP((VLOOKUP(1,$AT$67:$AW$71,4,0)),tab_fator[],2,0))-(VLOOKUP(AQ72,tab_fator[],2,0))+1),tab_fator[[#All],[Cont]:[Valor]],2,0)))/AP72)/60/60/24)),"hh:mm")) -> 53 Dias e 14:10 | K16: =(VLOOKUP(AQ72,tab_fator[],2,0)-(VLOOKUP(VLOOKUP(1,$AT$67:$AW$71,4,0),tab_fator[],2,0)))*-1 -> 2 | M16: Mina | N16: Armazem | P16: Armazem Valor | Q16: Elevador | S16: Elevador Valor | T16: Extração | V16: Extração Valor | W16: Ordem | Y16: Valor | Z16: ColsAjust | AA16: ColFator | AB16: AjsuteCol | AC16: Coluna | AD16: Linha | AE16: Valor Mínimo | AH16: Verificação | AK16: Atual | AN16: Ordem | AP16: Valor | AQ16: Multip. | AR16: Repre. | AT16: Ordem | AU16: Valor Real | AV16: Valor | AW16: Multip.
A17: ak | B17: =B16+1 -> 16 | C17: =C16*1000 -> 1e+45 | D17: =LEN(TEXT(C17,0)) -> 46 | F17: Submarino | G17: =_xlfn.XLOOKUP(1,AT77:AT81,AJ77:AJ81,"Erro",0,1) -> Sereias | H17: =VLOOKUP(G17,$AJ$7:$AW$82,13,0) -> 41.6 | I17: =VLOOKUP(G17,$AJ$7:$AW$82,14,0) -> at | J17: =_xlfn.CONCAT(INT(((((VLOOKUP(1,$AT$77:$AW$81,3,0)*(VLOOKUP(((VLOOKUP((VLOOKUP(1,$AT$77:$AW$81,4,0)),tab_fator[],2,0))-(VLOOKUP(AQ82,tab_fator[],2,0))+1),tab_fator[[#All],[Cont]:[Valor]],2,0)))/AP82)/60/60/24)))," Dias e ",TEXT(((((VLOOKUP(1,$AT$77:$AW$81,3,0)*(VLOOKUP(((VLOOKUP((VLOOKUP(1,$AT$77:$AW$81,4,0)),tab_fator[],2,0))-(VLOOKUP(AQ82,tab_fator[],2,0))+1),tab_fator[[#All],[Cont]:[Valor]],2,0)))/AP82)/60/60/24)),"hh:mm")) -> 130 Dias e 11:35 | K17: =(VLOOKUP(AQ82,tab_fator[],2,0)-(VLOOKUP(VLOOKUP(1,$AT$77:$AW$81,4,0),tab_fator[],2,0)))*-1 -> 2 | M17: Seletina | N17: 48.1 | O17: az | P17: =N17*(VLOOKUP(O17,tab_fator[],3,0)) -> 4.81e+91 | Q17: 51.8 | R17: az | S17: =Q17*(VLOOKUP(R17,tab_fator[],3,0)) -> 5.18e+91 | T17: 46 | U17: az | V17: =T17*(VLOOKUP(U17,tab_fator[],3,0)) -> 4.6e+91 | W17: =_xlfn.RANK.EQ(V17,$V17:$V21) -> 5 | Y17: =MIN(V17,S17,P17) -> 4.6e+91 | Z17: =MATCH(Y17,M17:V17,0) -> 10 | AA17: =COLUMN($L$1) -> 12 | AB17: 2 | AC17: =Z17+AA17-AB17 -> 20 | AD17: =ROW(X17) -> 17 | AE17: {=INDIRECT(ADDRESS(AD17,AC17,1,1))} -> 46 | AF17: {=INDIRECT(ADDRESS(AD17,AC17+1,1,1))} -> az | AH17: =IF(AND(V17<S17,V17<P17),"Equilibrado","Ver") -> Equilibrado | AJ17: Seletina | AK17: 5 | AL17: =VLOOKUP(I11,tab_fator[],2,0)-VLOOKUP(AQ17,tab_fator[],2,0) -> 4 | AM17: =IF(AN17+AT17=6,"Equilibrado","Ver") -> Equilibrado | AN17: =_xlfn.RANK.EQ(AO17,AO17:AO21) -> 5 | AO17: =AP17*(VLOOKUP(AQ17,tab_fator[],3,0)) -> 2.71e+92 | AP17: ='Transformação-Normal'!Q14 -> 271 | AQ17: ='Transformação-Normal'!R14 -> az | AR17: =AO17/SUM(AO17:AO21) -> 0.0016693257 | AS17: =(AP17*VLOOKUP(AQ17,tab_fator[],3,0))+ (AP18*VLOOKUP(AQ18,tab_fator[],3,0))+ (AP19*VLOOKUP(AQ19,tab_fator[],3,0))+ (AP20*VLOOKUP(AQ20,tab_fator[],3,0))+ (AP21*VLOOKUP(AQ21,tab_fator[],3,0)) -> 1.62341e+95 | AT17: =_xlfn.RANK.EQ(AU17,$AU$17:$AU$21,1) -> 1 | AU17: =AV17*(VLOOKUP(AW17,tab_fator[],3,0)) -> 1.44e+102 | AV17: 1.44 | AW17: bd
A18: al | B18: =B17+1 -> 17 | C18: =C17*1000 -> 1e+48 | D18: =LEN(TEXT(C18,0)) -> 49 | M18: Ametista | N18: 1.13 | O18: ba | P18: =N18*(VLOOKUP(O18,tab_fator[],3,0)) -> 1.13e+93 | Q18: 1.13 | R18: ba | S18: =Q18*(VLOOKUP(R18,tab_fator[],3,0)) -> 1.13e+93 | T18: 1.08 | U18: ba | V18: =T18*(VLOOKUP(U18,tab_fator[],3,0)) -> 1.08e+93 | W18: =_xlfn.RANK.EQ(V18,$V17:$V21) -> 4 | Y18: =MIN(V18,S18,P18) -> 1.08e+93 | Z18: =MATCH(Y18,M18:V18,0) -> 10 | AA18: =COLUMN($L$1) -> 12 | AB18: 2 | AC18: =Z18+AA18-AB18 -> 20 | AD18: =ROW(X18) -> 18 | AE18: {=INDIRECT(ADDRESS(AD18,AC18,1,1))} -> 1.08 | AF18: {=INDIRECT(ADDRESS(AD18,AC18+1,1,1))} -> ba | AH18: =IF(AND(V18<S18,V18<P18),"Equilibrado","Ver") -> Equilibrado | AJ18: Ametista | AK18: 5 | AL18: =VLOOKUP(I11,tab_fator[],2,0)-VLOOKUP(AQ18,tab_fator[],2,0) -> 3 | AM18: =IF(AN18+AT18=6,"Equilibrado","Ver") -> Equilibrado | AN18: =_xlfn.RANK.EQ(AO18,AO17:AO21) -> 4 | AO18: =AP18*(VLOOKUP(AQ18,tab_fator[],3,0)) -> 6.37e+93 | AP18: ='Transformação-Normal'!Q15 -> 6.37 | AQ18: ='Transformação-Normal'!R15 -> ba | AR18: =AO18/SUM(AO17:AO21) -> 0.039238393 | AS18: =_xlfn.XLOOKUP((LEN(TEXT(AS17,0))),tab_fator[Dgts],tab_fator[Fator],"errro",-1,1) -> ba | AT18: =_xlfn.RANK.EQ(AU18,$AU$17:$AU$21,1) -> 2 | AU18: =AV18*(VLOOKUP(AW18,tab_fator[],3,0)) -> 4.02e+103 | AV18: 40.2 | AW18: bd
A19: am | B19: =B18+1 -> 18 | C19: =C18*1000 -> 1e+51 | D19: =LEN(TEXT(C19,0)) -> 52 | G19: Tenho | H19: Meta | M19: Safira | N19: 2.5 | O19: ba | P19: =N19*(VLOOKUP(O19,tab_fator[],3,0)) -> 2.5e+93 | Q19: 2.5 | R19: ba | S19: =Q19*(VLOOKUP(R19,tab_fator[],3,0)) -> 2.5e+93 | T19: 2.39 | U19: ba | V19: =T19*(VLOOKUP(U19,tab_fator[],3,0)) -> 2.39e+93 | W19: =_xlfn.RANK.EQ(V19,$V17:$V21) -> 3 | Y19: =MIN(V19,S19,P19) -> 2.39e+93 | Z19: =MATCH(Y19,M19:V19,0) -> 10 | AA19: =COLUMN($L$1) -> 12 | AB19: 2 | AC19: =Z19+AA19-AB19 -> 20 | AD19: =ROW(X19) -> 19 | AE19: {=INDIRECT(ADDRESS(AD19,AC19,1,1))} -> 2.39 | AF19: {=INDIRECT(ADDRESS(AD19,AC19+1,1,1))} -> ba | AH19: =IF(AND(V19<S19,V19<P19),"Equilibrado","Ver") -> Equilibrado | AJ19: Safira | AK19: 5 | AL19: =VLOOKUP(I11,tab_fator[],2,0)-VLOOKUP(AQ19,tab_fator[],2,0) -> 3 | AM19: =IF(AN19+AT19=6,"Equilibrado","Ver") -> Equilibrado | AN19: =_xlfn.RANK.EQ(AO19,AO17:AO21) -> 3 | AO19: =AP19*(VLOOKUP(AQ19,tab_fator[],3,0)) -> 1.41e+94 | AP19: ='Transformação-Normal'!Q16 -> 14.1 | AQ19: ='Transformação-Normal'!R16 -> ba | AR19: =AO19/SUM(AO17:AO21) -> 0.086854214 | AS19: =VLOOKUP(AS18,tab_fator[],3,0) -> 1e+93 | AT19: =_xlfn.RANK.EQ(AU19,$AU$17:$AU$21,1) -> 3 | AU19: =AV19*(VLOOKUP(AW19,tab_fator[],3,0)) -> 2.84e+104 | AV19: 284 | AW19: bd
A20: an | B20: 19 | C20: =C19*1000 -> 1e+54 | D20: =LEN(TEXT(C20,0)) -> 55 | F20: 100X - 5M | G20: 18 | H20: 25 | I20: =G20/H20 -> 0.72 | M20: Cristal | N20: 17.5 | O20: ba | P20: =N20*(VLOOKUP(O20,tab_fator[],3,0)) -> 1.75e+94 | Q20: 17.5 | R20: ba | S20: =Q20*(VLOOKUP(R20,tab_fator[],3,0)) -> 1.75e+94 | T20: 8.89 | U20: ba | V20: =T20*(VLOOKUP(U20,tab_fator[],3,0)) -> 8.89e+93 | W20: =_xlfn.RANK.EQ(V20,$V17:$V21) -> 2 | Y20: =MIN(V20,S20,P20) -> 8.89e+93 | Z20: =MATCH(Y20,M20:V20,0) -> 10 | AA20: =COLUMN($L$1) -> 12 | AB20: 2 | AC20: =Z20+AA20-AB20 -> 20 | AD20: =ROW(X20) -> 20 | AE20: {=INDIRECT(ADDRESS(AD20,AC20,1,1))} -> 8.89 | AF20: {=INDIRECT(ADDRESS(AD20,AC20+1,1,1))} -> ba | AH20: =IF(AND(V20<S20,V20<P20),"Equilibrado","Ver") -> Equilibrado | AJ20: Cristal | AK20: 5 | AL20: =VLOOKUP(I11,tab_fator[],2,0)-VLOOKUP(AQ20,tab_fator[],2,0) -> 3 | AM20: =IF(AN20+AT20=6,"Equilibrado","Ver") -> Equilibrado | AN20: =_xlfn.RANK.EQ(AO20,AO17:AO21) -> 2 | AO20: =AP20*(VLOOKUP(AQ20,tab_fator[],3,0)) -> 5.25e+94 | AP20: ='Transformação-Normal'!Q17 -> 52.5 | AQ20: ='Transformação-Normal'!R17 -> ba | AR20: =AO20/SUM(AO17:AO21) -> 0.32339335 | AT20: =_xlfn.RANK.EQ(AU20,$AU$17:$AU$21,1) -> 4 | AU20: =AV20*(VLOOKUP(AW20,tab_fator[],3,0)) -> 2.14e+105 | AV20: 2.14 | AW20: be
A21: ao | B21: =B20+1 -> 20 | C21: =C20*1000 -> 1e+57 | D21: =LEN(TEXT(C21,0)) -> 58 | M21: Jade | N21: 20.3 | O21: ba | P21: =N21*(VLOOKUP(O21,tab_fator[],3,0)) -> 2.03e+94 | Q21: 20.4 | R21: ba | S21: =Q21*(VLOOKUP(R21,tab_fator[],3,0)) -> 2.04e+94 | T21: 15.1 | U21: ba | V21: =T21*(VLOOKUP(U21,tab_fator[],3,0)) -> 1.51e+94 | W21: =_xlfn.RANK.EQ(V21,$V17:$V21) -> 1 | Y21: =MIN(V21,S21,P21) -> 1.51e+94 | Z21: =MATCH(Y21,M21:V21,0) -> 10 | AA21: =COLUMN($L$1) -> 12 | AB21: 2 | AC21: =Z21+AA21-AB21 -> 20 | AD21: =ROW(X21) -> 21 | AE21: {=INDIRECT(ADDRESS(AD21,AC21,1,1))} -> 15.1 | AF21: {=INDIRECT(ADDRESS(AD21,AC21+1,1,1))} -> ba | AH21: =IF(AND(V21<S21,V21<P21),"Equilibrado","Ver") -> Equilibrado | AJ21: Jade | AK21: 5 | AL21: =VLOOKUP(I11,tab_fator[],2,0)-VLOOKUP(AQ21,tab_fator[],2,0) -> 3 | AM21: =IF(AN21+AT21=6,"Equilibrado","Ver") -> Equilibrado | AN21: =_xlfn.RANK.EQ(AO21,AO17:AO21) -> 1 | AO21: =AP21*(VLOOKUP(AQ21,tab_fator[],3,0)) -> 8.91e+94 | AP21: ='Transformação-Normal'!Q18 -> 89.1 | AQ21: ='Transformação-Normal'!R18 -> ba | AR21: =AO21/SUM(AO17:AO21) -> 0.54884472 | AT21: =_xlfn.RANK.EQ(AU21,$AU$17:$AU$21,1) -> 5 | AU21: =AV21*(VLOOKUP(AW21,tab_fator[],3,0)) -> 7.87e+105 | AV21: 7.87 | AW21: be
A22: ap | B22: =B21+1 -> 21 | C22: =C21*1000 -> 1e+60 | D22: =LEN(TEXT(C22,0)) -> 61 | F22: Artefatos | G22: Ativo | H22: Tempo | AJ22: Total | AK22: =CONCATENATE(SUM(AK17:AK21)," / ",6*5) -> 25 / 30 | AP22: =IF(AS17/AS19<10,(TEXT(AS17/AS19,"#,##")),IF(AS17/AS19<100,TEXT(AS17/AS19,"##,#"),TEXT(AS17/AS19,"###"))) -> 162 | AQ22: =AS18 -> ba | AT22: =IF((AP22*VLOOKUP(AQ22,tab_fator[],3,0))>(_xlfn.XLOOKUP(1,AT17:AT21,AV17:AV21,"",0,1)*VLOOKUP((_xlfn.XLOOKUP(1,AT17:AT21,AW17:AW21,"",0,1)),tab_fator[],3,0)),"Pronto","Esperar") -> Esperar
A23: aq | B23: =B22+1 -> 22 | C23: =C22*1000 -> 1e+63 | D23: =LEN(TEXT(C23,0)) -> 64 | F23: 2 | G23: S | H23: Por tempo
A24: ar | B24: =B23+1 -> 23 | C24: =C23*1000 -> 1e+66 | D24: =LEN(TEXT(C24,0)) -> 67 | F24: 4 | G24: S | H24: Por tempo | AJ24: Dinheiro de Fogo
A25: as | B25: =B24+1 -> 24 | C25: =C24*1000 -> 1e+69 | D25: =LEN(TEXT(C25,0)) -> 70 | F25: 5 | H25: Por tempo | M25: Dinheiro de Fogo | AJ25: Mina | AK25: Prestigo | AL25: GAP | AM25: Verificação | AN25: Valor OffLine | AT25: Próximo Prestigio
A26: at | B26: =B25+1 -> 25 | C26: =C25*1000 -> 1e+72 | D26: =LEN(TEXT(C26,0)) -> 73 | F26: 10 | G26: S | H26: Por tempo | M26: Mina | N26: Armazem | P26: Armazem Valor | Q26: Elevador | S26: Elevador Valor | T26: Extração | V26: Extração Valor | W26: Ordem | Y26: Valor | Z26: ColsAjust | AA26: ColFator | AB26: AjsuteCol | AC26: Coluna | AD26: Linha | AE26: Valor Mínimo | AH26: Verificação | AK26: Atual | AN26: Ordem | AP26: Valor | AQ26: Multip. | AR26: Repre. | AT26: Ordem | AU26: Valor Real | AV26: Valor | AW26: Multip.
A27: au | B27: =B26+1 -> 26 | C27: =C26*1000 -> 1e+75 | D27: =LEN(TEXT(C27,0)) -> 76 | F27: 20 | H27: Por tempo | M27: Ambar | N27: 443 | O27: ay | P27: =N27*(VLOOKUP(O27,tab_fator[],3,0)) -> 4.43e+89 | Q27: 426 | R27: ay | S27: =Q27*(VLOOKUP(R27,tab_fator[],3,0)) -> 4.26e+89 | T27: 401 | U27: ay | V27: =T27*(VLOOKUP(U27,tab_fator[],3,0)) -> 4.01e+89 | W27: =_xlfn.RANK.EQ(V27,$V27:$V31) -> 5 | Y27: =MIN(V27,S27,P27) -> 4.01e+89 | Z27: =MATCH(Y27,M27:V27,0) -> 10 | AA27: =COLUMN($L$1) -> 12 | AB27: 2 | AC27: =Z27+AA27-AB27 -> 20 | AD27: =ROW(X27) -> 27 | AE27: {=INDIRECT(ADDRESS(AD27,AC27,1,1))} -> 401 | AF27: {=INDIRECT(ADDRESS(AD27,AC27+1,1,1))} -> ay | AH27: =IF(AND(V27<S27,V27<P27),"Equilibrado","Ver") -> Equilibrado | AJ27: Ambar | AK27: 5 | AL27: =VLOOKUP($I$12,tab_fator[],2,0)-VLOOKUP(AQ27,tab_fator[],2,0) -> 3 | AM27: =IF(AN27+AT27=6,"Equilibrado","Ver") -> Equilibrado | AN27: =_xlfn.RANK.EQ(AO27,AO27:AO31) -> 5 | AO27: =AP27*(VLOOKUP(AQ27,tab_fator[],3,0)) -> 2.37e+90 | AP27: ='Transformação-Normal'!Q21 -> 2.37 | AQ27: ='Transformação-Normal'!R21 -> az | AR27: =AO27/SUM(AO27:AO31) -> 0.018695275 | AS27: =(AP27*VLOOKUP(AQ27,tab_fator[],3,0))+ (AP28*VLOOKUP(AQ28,tab_fator[],3,0))+ (AP29*VLOOKUP(AQ29,tab_fator[],3,0))+ (AP30*VLOOKUP(AQ30,tab_fator[],3,0))+ (AP31*VLOOKUP(AQ31,tab_fator[],3,0)) -> 1.2677e+92 | AT27: =_xlfn.RANK.EQ(AU27,$AU$27:$AU$31,1) -> 1 | AU27: =AV27*(VLOOKUP(AW27,tab_fator[],3,0)) -> 2.81e+99 | AV27: 2.81 | AW27: bc
A28: av | B28: =B27+1 -> 27 | C28: =C27*1000 -> 1e+78 | D28: =LEN(TEXT(C28,0)) -> 79 | F28: 25 | H28: Por tempo | M28: Pedra do Sol | N28: 2.02 | O28: az | P28: =N28*(VLOOKUP(O28,tab_fator[],3,0)) -> 2.02e+90 | Q28: 1.95 | R28: az | S28: =Q28*(VLOOKUP(R28,tab_fator[],3,0)) -> 1.95e+90 | T28: 1.72 | U28: az | V28: =T28*(VLOOKUP(U28,tab_fator[],3,0)) -> 1.72e+90 | W28: =_xlfn.RANK.EQ(V28,$V27:$V31) -> 4 | Y28: =MIN(V28,S28,P28) -> 1.72e+90 | Z28: =MATCH(Y28,M28:V28,0) -> 10 | AA28: =COLUMN($L$1) -> 12 | AB28: 2 | AC28: =Z28+AA28-AB28 -> 20 | AD28: =ROW(X28) -> 28 | AE28: {=INDIRECT(ADDRESS(AD28,AC28,1,1))} -> 1.72 | AF28: {=INDIRECT(ADDRESS(AD28,AC28+1,1,1))} -> az | AH28: =IF(AND(V28<S28,V28<P28),"Equilibrado","Ver") -> Equilibrado | AJ28: Pedra do Sol | AK28: 5 | AL28: =VLOOKUP($I$12,tab_fator[],2,0)-VLOOKUP(AQ28,tab_fator[],2,0) -> 3 | AM28: =IF(AN28+AT28=6,"Equilibrado","Ver") -> Equilibrado | AN28: =_xlfn.RANK.EQ(AO28,AO27:AO31) -> 4 | AO28: =AP28*(VLOOKUP(AQ28,tab_fator[],3,0)) -> 1.01e+91 | AP28: ='Transformação-Normal'!Q22 -> 10.1 | AQ28: ='Transformação-Normal'!R22 -> az | AR28: =AO28/SUM(AO27:AO31) -> 0.079671847 | AS28: =_xlfn.XLOOKUP((LEN(TEXT(AS27,0))),tab_fator[Dgts],tab_fator[Fator],"errro",-1,1) -> az | AT28: =_xlfn.RANK.EQ(AU28,$AU$27:$AU$31,1) -> 2 | AU28: =AV28*(VLOOKUP(AW28,tab_fator[],3,0)) -> 3.99e+100 | AV28: 39.9 | AW28: bc
A29: aw | B29: =B28+1 -> 28 | C29: =C28*1000 -> 1e+81 | D29: =LEN(TEXT(C29,0)) -> 82 | F29: 50 | H29: Por tempo | M29: Topázio | N29: 2.11 | O29: az | P29: =N29*(VLOOKUP(O29,tab_fator[],3,0)) -> 2.11e+90 | Q29: 2.03 | R29: az | S29: =Q29*(VLOOKUP(R29,tab_fator[],3,0)) -> 2.03e+90 | T29: 1.95 | U29: az | V29: =T29*(VLOOKUP(U29,tab_fator[],3,0)) -> 1.95e+90 | W29: =_xlfn.RANK.EQ(V29,$V27:$V31) -> 3 | Y29: =MIN(V29,S29,P29) -> 1.95e+90 | Z29: =MATCH(Y29,M29:V29,0) -> 10 | AA29: =COLUMN($L$1) -> 12 | AB29: 2 | AC29: =Z29+AA29-AB29 -> 20 | AD29: =ROW(X29) -> 29 | AE29: {=INDIRECT(ADDRESS(AD29,AC29,1,1))} -> 1.95 | AF29: {=INDIRECT(ADDRESS(AD29,AC29+1,1,1))} -> az | AH29: =IF(AND(V29<S29,V29<P29),"Equilibrado","Ver") -> Equilibrado | AJ29: Topázio | AK29: 5 | AL29: =VLOOKUP($I$12,tab_fator[],2,0)-VLOOKUP(AQ29,tab_fator[],2,0) -> 3 | AM29: =IF(AN29+AT29=6,"Equilibrado","Ver") -> Equilibrado | AN29: =_xlfn.RANK.EQ(AO29,AO27:AO31) -> 3 | AO29: =AP29*(VLOOKUP(AQ29,tab_fator[],3,0)) -> 1.15e+91 | AP29: ='Transformação-Normal'!Q23 -> 11.5 | AQ29: ='Transformação-Normal'!R23 -> az | AR29: =AO29/SUM(AO27:AO31) -> 0.090715469 | AS29: =VLOOKUP(AS28,tab_fator[],3,0) -> 1e+90 | AT29: =_xlfn.RANK.EQ(AU29,$AU$27:$AU$31,1) -> 3 | AU29: =AV29*(VLOOKUP(AW29,tab_fator[],3,0)) -> 3.4e+101 | AV29: 340 | AW29: bc
A30: ax | B30: =B29+1 -> 29 | C30: =C29*1000 -> 1e+84 | D30: =LEN(TEXT(C30,0)) -> 85 | F30: 75 | H30: Por tempo | M30: Platina | N30: 8.68 | O30: az | P30: =N30*(VLOOKUP(O30,tab_fator[],3,0)) -> 8.68e+90 | Q30: 8.36 | R30: az | S30: =Q30*(VLOOKUP(R30,tab_fator[],3,0)) -> 8.36e+90 | T30: 6.32 | U30: az | V30: =T30*(VLOOKUP(U30,tab_fator[],3,0)) -> 6.32e+90 | W30: =_xlfn.RANK.EQ(V30,$V27:$V31) -> 2 | Y30: =MIN(V30,S30,P30) -> 6.32e+90 | Z30: =MATCH(Y30,M30:V30,0) -> 10 | AA30: =COLUMN($L$1) -> 12 | AB30: 2 | AC30: =Z30+AA30-AB30 -> 20 | AD30: =ROW(X30) -> 30 | AE30: {=INDIRECT(ADDRESS(AD30,AC30,1,1))} -> 6.32 | AF30: {=INDIRECT(ADDRESS(AD30,AC30+1,1,1))} -> az | AH30: =IF(AND(V30<S30,V30<P30),"Equilibrado","Ver") -> Equilibrado | AJ30: Platina | AK30: 5 | AL30: =VLOOKUP($I$12,tab_fator[],2,0)-VLOOKUP(AQ30,tab_fator[],2,0) -> 3 | AM30: =IF(AN30+AT30=6,"Equilibrado","Ver") -> Equilibrado | AN30: =_xlfn.RANK.EQ(AO30,AO27:AO31) -> 2 | AO30: =AP30*(VLOOKUP(AQ30,tab_fator[],3,0)) -> 3.73e+91 | AP30: ='Transformação-Normal'!Q24 -> 37.3 | AQ30: ='Transformação-Normal'!R24 -> az | AR30: =AO30/SUM(AO27:AO31) -> 0.29423365 | AT30: =_xlfn.RANK.EQ(AU30,$AU$27:$AU$31,1) -> 4 | AU30: =AV30*(VLOOKUP(AW30,tab_fator[],3,0)) -> 2.36e+102 | AV30: 2.36 | AW30: bd
A31: ay | B31: =B30+1 -> 30 | C31: =C30*1000 -> 1e+87 | D31: =LEN(TEXT(C31,0)) -> 88 | F31: 100 | H31: Por tempo | M31: Obsidiana | N31: 12 | O31: az | P31: =N31*(VLOOKUP(O31,tab_fator[],3,0)) -> 1.2e+91 | Q31: 12.5 | R31: az | S31: =Q31*(VLOOKUP(R31,tab_fator[],3,0)) -> 1.25e+91 | T31: 11.1 | U31: az | V31: =T31*(VLOOKUP(U31,tab_fator[],3,0)) -> 1.11e+91 | W31: =_xlfn.RANK.EQ(V31,$V27:$V31) -> 1 | Y31: =MIN(V31,S31,P31) -> 1.11e+91 | Z31: =MATCH(Y31,M31:V31,0) -> 10 | AA31: =COLUMN($L$1) -> 12 | AB31: 2 | AC31: =Z31+AA31-AB31 -> 20 | AD31: =ROW(X31) -> 31 | AE31: {=INDIRECT(ADDRESS(AD31,AC31,1,1))} -> 11.1 | AF31: {=INDIRECT(ADDRESS(AD31,AC31+1,1,1))} -> az | AH31: =IF(AND(V31<S31,V31<P31),"Equilibrado","Ver") -> Equilibrado | AJ31: Obsidiana | AK31: 5 | AL31: =VLOOKUP($I$12,tab_fator[],2,0)-VLOOKUP(AQ31,tab_fator[],2,0) -> 3 | AM31: =IF(AN31+AT31=6,"Equilibrado","Ver") -> Equilibrado | AN31: =_xlfn.RANK.EQ(AO31,AO27:AO31) -> 1 | AO31: =AP31*(VLOOKUP(AQ31,tab_fator[],3,0)) -> 6.55e+91 | AP31: ='Transformação-Normal'!Q25 -> 65.5 | AQ31: ='Transformação-Normal'!R25 -> az | AR31: =AO31/SUM(AO27:AO31) -> 0.51668376 | AT31: =_xlfn.RANK.EQ(AU31,$AU$27:$AU$31,1) -> 5 | AU31: =AV31*(VLOOKUP(AW31,tab_fator[],3,0)) -> 5.89e+102 | AV31: 5.89 | AW31: bd
A32: az | B32: =B31+1 -> 31 | C32: =C31*1000 -> 1e+90 | D32: =LEN(TEXT(C32,0)) -> 91 | F32: 200 | H32: Por tempo | AJ32: Total | AK32: =CONCATENATE(SUM(AK27:AK31)," / ",6*5) -> 25 / 30 | AP32: =IF(AS27/AS29<10,(TEXT(AS27/AS29,"#,##")),IF(AS27/AS29<100,TEXT(AS27/AS29,"##,#"),TEXT(AS27/AS29,"###"))) -> 127 | AQ32: =AS28 -> az | AT32: =IF((AP32*VLOOKUP(AQ32,tab_fator[],3,0))>(_xlfn.XLOOKUP(1,AT27:AT31,AV27:AV31,"",0,1)*VLOOKUP((_xlfn.XLOOKUP(1,AT27:AT31,AW27:AW31,"",0,1)),tab_fator[],3,0)),"Pronto","Esperar") -> Esperar
A33: ba | B33: =B32+1 -> 32 | C33: =C32*1000 -> 1e+93 | D33: =LEN(TEXT(C33,0)) -> 94 | F33: 500 | H33: Por tempo
A34: bb | B34: =B33+1 -> 33 | C34: =C33*1000 -> 1e+96 | D34: =LEN(TEXT(C34,0)) -> 97 | F34: 1000 | H34: Por tempo | AJ34: Dinheiro da Aurora
A35: bc | B35: =B34+1 -> 34 | C35: =C34*1000 -> 1e+99 | D35: =LEN(TEXT(C35,0)) -> 100 | F35: 4000 | H35: Por tempo | M35: Dinheiro da Aurora | AJ35: Mina | AK35: Prestigo | AL35: GAP | AM35: Verificação | AN35: Valor OffLine | AT35: Próximo Prestigio
A36: bd | B36: =B35+1 -> 35 | C36: =C35*1000 -> 1e+102 | D36: =LEN(TEXT(C36,0)) -> 103 | F36: 5000 | H36: Por tempo | M36: Mina | N36: Armazem | P36: Armazem Valor | Q36: Elevador | S36: Elevador Valor | T36: Extração | V36: Extração Valor | W36: Ordem | Y36: Valor | Z36: ColsAjust | AA36: ColFator | AB36: AjsuteCol | AC36: Coluna | AD36: Linha | AE36: Valor Mínimo | AH36: Verificação | AK36: Atual | AN36: Ordem | AP36: Valor | AQ36: Multip. | AR36: Repre. | AT36: Ordem | AU36: Valor Real | AV36: Valor | AW36: Multip.
A37: be | B37: =B36+1 -> 36 | C37: =C36*1000 -> 1e+105 | D37: =LEN(TEXT(C37,0)) -> 106 | M37: Heliodoro | N37: 1.09 | O37: aw | P37: =N37*(VLOOKUP(O37,tab_fator[],3,0)) -> 1.09e+81 | Q37: 1.11 | R37: aw | S37: =Q37*(VLOOKUP(R37,tab_fator[],3,0)) -> 1.11e+81 | T37: 1.03 | U37: aw | V37: =T37*(VLOOKUP(U37,tab_fator[],3,0)) -> 1.03e+81 | W37: =_xlfn.RANK.EQ(V37,$V37:$V41) -> 1 | Y37: =MIN(V37,S37,P37) -> 1.03e+81 | Z37: =MATCH(Y37,M37:V37,0) -> 10 | AA37: =COLUMN($L$1) -> 12 | AB37: 2 | AC37: =Z37+AA37-AB37 -> 20 | AD37: =ROW(X37) -> 37 | AE37: {=INDIRECT(ADDRESS(AD37,AC37,1,1))} -> 1.03 | AF37: {=INDIRECT(ADDRESS(AD37,AC37+1,1,1))} -> aw | AH37: =IF(AND(V37<S37,V37<P37),"Equilibrado","Ver") -> Equilibrado | AJ37: Heliodoro | AK37: 5 | AL37: =VLOOKUP($I$13,tab_fator[],2,0)-VLOOKUP(AQ37,tab_fator[],2,0) -> 2 | AM37: =IF(AN37+AT37=6,"Equilibrado","Ver") -> Equilibrado | AN37: =_xlfn.RANK.EQ(AO37,AO37:AO41) -> 1 | AO37: =AP37*(VLOOKUP(AQ37,tab_fator[],3,0)) -> 6.08e+81 | AP37: ='Transformação-Normal'!Q28 -> 6.08 | AQ37: ='Transformação-Normal'!R28 -> aw | AR37: =AO37/SUM(AO37:AO41) -> 0.42783759 | AS37: =(AP37*VLOOKUP(AQ37,tab_fator[],3,0))+ (AP38*VLOOKUP(AQ38,tab_fator[],3,0))+ (AP39*VLOOKUP(AQ39,tab_fator[],3,0))+ (AP40*VLOOKUP(AQ40,tab_fator[],3,0))+ (AP41*VLOOKUP(AQ41,tab_fator[],3,0)) -> 1.4211e+82 | AT37: =_xlfn.RANK.EQ(AU37,$AU$37:$AU$41,1) -> 5 | AU37: =AV37*(VLOOKUP(AW37,tab_fator[],3,0)) -> 8.26e+100 | AV37: 82.6 | AW37: bc
A38: bf | B38: =B37+1 -> 37 | C38: =C37*1000 -> 1e+108 | D38: =LEN(TEXT(C38,0)) -> 109 | F38: Soma Off | G38: =SUMIF(G23:G36,"S",F23:F36)+4 -> 20 | M38: Realgar | N38: 32.4 | O38: av | P38: =N38*(VLOOKUP(O38,tab_fator[],3,0)) -> 3.24e+79 | Q38: 32.6 | R38: av | S38: =Q38*(VLOOKUP(R38,tab_fator[],3,0)) -> 3.26e+79 | T38: 31.9 | U38: av | V38: =T38*(VLOOKUP(U38,tab_fator[],3,0)) -> 3.19e+79 | W38: =_xlfn.RANK.EQ(V38,$V37:$V41) -> 5 | Y38: =MIN(V38,S38,P38) -> 3.19e+79 | Z38: =MATCH(Y38,M38:V38,0) -> 10 | AA38: =COLUMN($L$1) -> 12 | AB38: 2 | AC38: =Z38+AA38-AB38 -> 20 | AD38: =ROW(X38) -> 38 | AE38: {=INDIRECT(ADDRESS(AD38,AC38,1,1))} -> 31.9 | AF38: {=INDIRECT(ADDRESS(AD38,AC38+1,1,1))} -> av | AH38: =IF(AND(V38<S38,V38<P38),"Equilibrado","Ver") -> Equilibrado | AJ38: Realgar | AK38: 4 | AL38: =VLOOKUP($I$13,tab_fator[],2,0)-VLOOKUP(AQ38,tab_fator[],2,0) -> 3 | AM38: =IF(AN38+AT38=6,"Equilibrado","Ver") -> Equilibrado | AN38: =_xlfn.RANK.EQ(AO38,AO37:AO41) -> 5 | AO38: =AP38*(VLOOKUP(AQ38,tab_fator[],3,0)) -> 1.88e+80 | AP38: ='Transformação-Normal'!Q29 -> 188 | AQ38: ='Transformação-Normal'!R29 -> av | AR38: =AO38/SUM(AO37:AO41) -> 0.013229189 | AS38: =_xlfn.XLOOKUP((LEN(TEXT(AS37,0))),tab_fator[Dgts],tab_fator[Fator],"errro",-1,1) -> aw | AT38: =_xlfn.RANK.EQ(AU38,$AU$37:$AU$41,1) -> 1 | AU38: =AV38*(VLOOKUP(AW38,tab_fator[],3,0)) -> 1.51e+88 | AV38: 15.1 | AW38: ay
A39: bg | B39: =B38+1 -> 38 | C39: =C38*1000 -> 1e+111 | D39: =LEN(TEXT(C39,0)) -> 112 | F39: Buster Anuncio | G39: 2.95 | M39: Alexandrita | N39: 289 | O39: av | P39: =N39*(VLOOKUP(O39,tab_fator[],3,0)) -> 2.89e+80 | Q39: 681 | R39: av | S39: =Q39*(VLOOKUP(R39,tab_fator[],3,0)) -> 6.81e+80 | T39: 282 | U39: av | V39: =T39*(VLOOKUP(U39,tab_fator[],3,0)) -> 2.82e+80 | W39: =_xlfn.RANK.EQ(V39,$V37:$V41) -> 3 | Y39: =MIN(V39,S39,P39) -> 2.82e+80 | Z39: =MATCH(Y39,M39:V39,0) -> 10 | AA39: =COLUMN($L$1) -> 12 | AB39: 2 | AC39: =Z39+AA39-AB39 -> 20 | AD39: =ROW(X39) -> 39 | AE39: {=INDIRECT(ADDRESS(AD39,AC39,1,1))} -> 282 | AF39: {=INDIRECT(ADDRESS(AD39,AC39+1,1,1))} -> av | AH39: =IF(AND(V39<S39,V39<P39),"Equilibrado","Ver") -> Equilibrado | AJ39: Alexandrita | AK39: 4 | AL39: =VLOOKUP($I$13,tab_fator[],2,0)-VLOOKUP(AQ39,tab_fator[],2,0) -> 2 | AM39: =IF(AN39+AT39=6,"Equilibrado","Ver") -> Equilibrado | AN39: =_xlfn.RANK.EQ(AO39,AO37:AO41) -> 3 | AO39: =AP39*(VLOOKUP(AQ39,tab_fator[],3,0)) -> 1.66e+81 | AP39: ='Transformação-Normal'!Q30 -> 1.66 | AQ39: ='Transformação-Normal'!R30 -> aw | AR39: =AO39/SUM(AO37:AO41) -> 0.11681092 | AS39: =VLOOKUP(AS38,tab_fator[],3,0) -> 1e+81 | AT39: =_xlfn.RANK.EQ(AU39,$AU$37:$AU$41,1) -> 3 | AU39: =AV39*(VLOOKUP(AW39,tab_fator[],3,0)) -> 1.4e+91 | AV39: 14 | AW39: az
A40: bh | B40: =B39+1 -> 39 | C40: =C39*1000 -> 1e+114 | D40: =LEN(TEXT(C40,0)) -> 115 | M40: Celestina | N40: 46.5 | O40: av | P40: =N40*(VLOOKUP(O40,tab_fator[],3,0)) -> 4.65e+79 | Q40: 46.9 | R40: av | S40: =Q40*(VLOOKUP(R40,tab_fator[],3,0)) -> 4.69e+79 | T40: 44.6 | U40: av | V40: =T40*(VLOOKUP(U40,tab_fator[],3,0)) -> 4.46e+79 | W40: =_xlfn.RANK.EQ(V40,$V37:$V41) -> 4 | Y40: =MIN(V40,S40,P40) -> 4.46e+79 | Z40: =MATCH(Y40,M40:V40,0) -> 10 | AA40: =COLUMN($L$1) -> 12 | AB40: 2 | AC40: =Z40+AA40-AB40 -> 20 | AD40: =ROW(X40) -> 40 | AE40: {=INDIRECT(ADDRESS(AD40,AC40,1,1))} -> 44.6 | AF40: {=INDIRECT(ADDRESS(AD40,AC40+1,1,1))} -> av | AH40: =IF(AND(V40<S40,V40<P40),"Equilibrado","Ver") -> Equilibrado | AJ40: Celestina | AK40: 3 | AL40: =VLOOKUP($I$13,tab_fator[],2,0)-VLOOKUP(AQ40,tab_fator[],2,0) -> 3 | AM40: =IF(AN40+AT40=6,"Equilibrado","Ver") -> Equilibrado | AN40: =_xlfn.RANK.EQ(AO40,AO37:AO41) -> 4 | AO40: =AP40*(VLOOKUP(AQ40,tab_fator[],3,0)) -> 2.63e+80 | AP40: ='Transformação-Normal'!Q31 -> 263 | AQ40: ='Transformação-Normal'!R31 -> av | AR40: =AO40/SUM(AO37:AO41) -> 0.018506791 | AT40: =_xlfn.RANK.EQ(AU40,$AU$37:$AU$41,1) -> 2 | AU40: =AV40*(VLOOKUP(AW40,tab_fator[],3,0)) -> 6.28e+89 | AV40: 628 | AW40: ay
...

Sheet Transformação-Normal
A1: Fator | B1: Cont | C1: Valor | D1: Dgts
A2: - | B2: 1 | C2: 1 | D2: =LEN(TEXT(C2,0)) -> 1 | F2: Fator | G2: ='Idle-Normal'!G2/10 -> 5.9
A3: k | B3: =B2+1 -> 2 | C3: =C2*1000 -> 1000 | D3: =LEN(TEXT(C3,0)) -> 4
A4: m | B4: =B3+1 -> 3 | C4: =C3*1000 -> 1000000 | D4: =LEN(TEXT(C4,0)) -> 7
A5: b | B5: =B4+1 -> 4 | C5: =C4*1000 -> 1000000000 | D5: =LEN(TEXT(C5,0)) -> 10
A6: t | B6: =B5+1 -> 5 | C6: =C5*1000 -> 1000000000000 | D6: =LEN(TEXT(C6,0)) -> 13 | F6: Mina | G6: Produção | I6: Vlr Total | J6: Digtos R | K6: Letra R | L6: Verificação | M6: Valor Fator | N6: Digitos F | O6: VlrBaseFator | P6: VlrVisF | Q6: VlrVisFaFinal | R6: Letras F
A7: aa | B7: =B6+1 -> 6 | C7: =C6*1000 -> 1e+15 | D7: =LEN(TEXT(C7,0)) -> 16 | F7: Carvão | G7: ='Idle-Normal'!AE7 -> 403 | H7: ='Idle-Normal'!AF7 -> bb | I7: =G7*(VLOOKUP(H7,tab_fatorTestes[],3,0)) -> 4.03e+98 | J7: =LEN(TEXT(I7,0)) -> 99 | K7: {=_xlfn.XLOOKUP(J7,tab_fatorTestes[[#All],[Dgts]],tab_fatorTestes[[#All],[Fator]],"Erro",-1,1)} -> bb | L7: =K7=H7 -> TRUE | M7: =I7*$G$2 -> 2.3777e+99 | N7: =LEN(TEXT(M7,0)) -> 100 | O7: =VLOOKUP(R7,tab_fatorTestes[],3,0) -> 1e+99 | P7: =M7/O7 -> 2.3777 | Q7: =ROUND(P7,(IF(P7<10,2,IF(P7<100,1,IF(P7>100,0))))) -> 2.38 | R7: {=_xlfn.XLOOKUP(N7,tab_fatorTestes[[#All],[Dgts]],tab_fatorTestes[[#All],[Fator]],"Erro",-1,1)} -> bc
A8: ab | B8: =B7+1 -> 7 | C8: =C7*1000 -> 1e+18 | D8: =LEN(TEXT(C8,0)) -> 19 | F8: Ouro | G8: ='Idle-Normal'!AE8 -> 344 | H8: ='Idle-Normal'!AF8 -> bb | I8: =G8*(VLOOKUP(H8,tab_fatorTestes[],3,0)) -> 3.44e+98 | J8: =LEN(TEXT(I8,0)) -> 99 | K8: {=_xlfn.XLOOKUP(J8,tab_fatorTestes[[#All],[Dgts]],tab_fatorTestes[[#All],[Fator]],"Erro",-1,1)} -> bb | L8: =K8=H8 -> TRUE | M8: =I8*$G$2 -> 2.0296e+99 | N8: =LEN(TEXT(M8,0)) -> 100 | O8: =VLOOKUP(R8,tab_fatorTestes[],3,0) -> 1e+99 | P8: =M8/O8 -> 2.0296 | Q8: =ROUND(P8,(IF(P8<10,2,IF(P8<100,1,IF(P8>100,0))))) -> 2.03 | R8: {=_xlfn.XLOOKUP(N8,tab_fatorTestes[[#All],[Dgts]],tab_fatorTestes[[#All],[Fator]],"Erro",-1,1)} -> bc
A9: ac | B9: =B8+1 -> 8 | C9: =C8*1000 -> 1e+21 | D9: =LEN(TEXT(C9,0)) -> 22 | F9: Rubi | G9: ='Idle-Normal'!AE9 -> 1.16 | H9: ='Idle-Normal'!AF9 -> bc | I9: =G9*(VLOOKUP(H9,tab_fatorTestes[],3,0)) -> 1.16e+99 | J9: =LEN(TEXT(I9,0)) -> 100 | K9: {=_xlfn.XLOOKUP(J9,tab_fatorTestes[[#All],[Dgts]],tab_fatorTestes[[#All],[Fator]],"Erro",-1,1)} -> bc | L9: =K9=H9 -> TRUE | M9: =I9*$G$2 -> 6.844e+99 | N9: =LEN(TEXT(M9,0)) -> 100 | O9: =VLOOKUP(R9,tab_fatorTestes[],3,0) -> 1e+99 | P9: =M9/O9 -> 6.844 | Q9: =ROUND(P9,(IF(P9<10,2,IF(P9<100,1,IF(P9>100,0))))) -> 6.84 | R9: {=_xlfn.XLOOKUP(N9,tab_fatorTestes[[#All],[Dgts]],tab_fatorTestes[[#All],[Fator]],"Erro",-1,1)} -> bc
A10: ad | B10: =B9+1 -> 9 | C10: =C9*1000 -> 1e+24 | D10: =LEN(TEXT(C10,0)) -> 25 | F10: Diamante | G10: ='Idle-Normal'!AE10 -> 42.9 | H10: ='Idle-Normal'!AF10 -> at | I10: =G10*(VLOOKUP(H10,tab_fatorTestes[],3,0)) -> 4.29e+73 | J10: =LEN(TEXT(I10,0)) -> 74 | K10: {=_xlfn.XLOOKUP(J10,tab_fatorTestes[[#All],[Dgts]],tab_fatorTestes[[#All],[Fator]],"Erro",-1,1)} -> at | L10: =K10=H10 -> TRUE | M10: =I10*$G$2 -> 2.5311e+74 | N10: =LEN(TEXT(M10,0)) -> 75 | O10: =VLOOKUP(R10,tab_fatorTestes[],3,0) -> 1e+72 | P10: =M10/O10 -> 253.11 | Q10: =ROUND(P10,(IF(P10<10,2,IF(P10<100,1,IF(P10>100,0))))) -> 253 | R10: {=_xlfn.XLOOKUP(N10,tab_fatorTestes[[#All],[Dgts]],tab_fatorTestes[[#All],[Fator]],"Erro",-1,1)} -> at
A11: ae | B11: =B10+1 -> 10 | C11: =C10*1000 -> 1e+27 | D11: =LEN(TEXT(C11,0)) -> 28 | F11: Esmeralda | G11: ='Idle-Normal'!AE11 -> 14.5 | H11: ='Idle-Normal'!AF11 -> bb | I11: =G11*(VLOOKUP(H11,tab_fatorTestes[],3,0)) -> 1.45e+97 | J11: =LEN(TEXT(I11,0)) -> 98 | K11: {=_xlfn.XLOOKUP(J11,tab_fatorTestes[[#All],[Dgts]],tab_fatorTestes[[#All],[Fator]],"Erro",-1,1)} -> bb | L11: =K11=H11 -> TRUE | M11: =I11*$G$2 -> 8.555e+97 | N11: =LEN(TEXT(M11,0)) -> 98 | O11: =VLOOKUP(R11,tab_fatorTestes[],3,0) -> 1e+96 | P11: =M11/O11 -> 85.55 | Q11: =ROUND(P11,(IF(P11<10,2,IF(P11<100,1,IF(P11>100,0))))) -> 85.6 | R11: {=_xlfn.XLOOKUP(N11,tab_fatorTestes[[#All],[Dgts]],tab_fatorTestes[[#All],[Fator]],"Erro",-1,1)} -> bb
A12: af | B12: =B11+1 -> 11 | C12: =C11*1000 -> 1e+30 | D12: =LEN(TEXT(C12,0)) -> 31 | F12: Total | M12: =SUM(M7:M11) -> 1.133685e+100 | N12: =LEN(TEXT(M12,0)) -> 101 | O12: =VLOOKUP(R12,tab_fatorTestes[],3,0) -> 1e+99 | P12: =M12/O12 -> 11.33685 | Q12: =ROUND(P12,(IF(P12<10,2,IF(P12<100,1,IF(P12>100,0))))) -> 11.3 | R12: {=_xlfn.XLOOKUP(N12,tab_fatorTestes[[#All],[Dgts]],tab_fatorTestes[[#All],[Fator]],"Erro",-1,1)} -> bc
A13: ag | B13: =B12+1 -> 12 | C13: =C12*1000 -> 1e+33 | D13: =LEN(TEXT(C13,0)) -> 34
A14: ah | B14: =B13+1 -> 13 | C14: =C13*1000 -> 1e+36 | D14: =LEN(TEXT(C14,0)) -> 37 | F14: Seletina | G14: ='Idle-Normal'!AE17 -> 46 | H14: ='Idle-Normal'!AF17 -> az | I14: =G14*(VLOOKUP(H14,tab_fatorTestes[],3,0)) -> 4.6e+91 | J14: =LEN(TEXT(I14,0)) -> 92 | K14: {=_xlfn.XLOOKUP(J14,tab_fatorTestes[[#All],[Dgts]],tab_fatorTestes[[#All],[Fator]],"Erro",-1,1)} -> az | L14: =K14=H14 -> TRUE | M14: =I14*$G$2 -> 2.714e+92 | N14: =LEN(TEXT(M14,0)) -> 93 | O14: =VLOOKUP(R14,tab_fatorTestes[],3,0) -> 1e+90 | P14: =M14/O14 -> 271.4 | Q14: =ROUND(P14,(IF(P14<10,2,IF(P14<100,1,IF(P14>100,0))))) -> 271 | R14: {=_xlfn.XLOOKUP(N14,tab_fatorTestes[[#All],[Dgts]],tab_fatorTestes[[#All],[Fator]],"Erro",-1,1)} -> az
A15: ai | B15: =B14+1 -> 14 | C15: =C14*1000 -> 1e+39 | D15: =LEN(TEXT(C15,0)) -> 40 | F15: Ametista | G15: ='Idle-Normal'!AE18 -> 1.08 | H15: ='Idle-Normal'!AF18 -> ba | I15: =G15*(VLOOKUP(H15,tab_fatorTestes[],3,0)) -> 1.08e+93 | J15: =LEN(TEXT(I15,0)) -> 94 | K15: {=_xlfn.XLOOKUP(J15,tab_fatorTestes[[#All],[Dgts]],tab_fatorTestes[[#All],[Fator]],"Erro",-1,1)} -> ba | L15: =K15=H15 -> TRUE | M15: =I15*$G$2 -> 6.372e+93 | N15: =LEN(TEXT(M15,0)) -> 94 | O15: =VLOOKUP(R15,tab_fatorTestes[],3,0) -> 1e+93 | P15: =M15/O15 -> 6.372 | Q15: =ROUND(P15,(IF(P15<10,2,IF(P15<100,1,IF(P15>100,0))))) -> 6.37 | R15: {=_xlfn.XLOOKUP(N15,tab_fatorTestes[[#All],[Dgts]],tab_fatorTestes[[#All],[Fator]],"Erro",-1,1)} -> ba
A16: aj | B16: =B15+1 -> 15 | C16: =C15*1000 -> 1e+42 | D16: =LEN(TEXT(C16,0)) -> 43 | F16: Safira | G16: ='Idle-Normal'!AE19 -> 2.39 | H16: ='Idle-Normal'!AF19 -> ba | I16: =G16*(VLOOKUP(H16,tab_fatorTestes[],3,0)) -> 2.39e+93 | J16: =LEN(TEXT(I16,0)) -> 94 | K16: {=_xlfn.XLOOKUP(J16,tab_fatorTestes[[#All],[Dgts]],tab_fatorTestes[[#All],[Fator]],"Erro",-1,1)} -> ba | L16: =K16=H16 -> TRUE | M16: =I16*$G$2 -> 1.4101e+94 | N16: =LEN(TEXT(M16,0)) -> 95 | O16: =VLOOKUP(R16,tab_fatorTestes[],3,0) -> 1e+93 | P16: =M16/O16 -> 14.101 | Q16: =ROUND(P16,(IF(P16<10,2,IF(P16<100,1,IF(P16>100,0))))) -> 14.1 | R16: {=_xlfn.XLOOKUP(N16,tab_fatorTestes[[#All],[Dgts]],tab_fatorTestes[[#All],[Fator]],"Erro",-1,1)} -> ba
A17: ak | B17: =B16+1 -> 16 | C17: =C16*1000 -> 1e+45 | D17: =LEN(TEXT(C17,0)) -> 46 | F17: Cristal | G17: ='Idle-Normal'!AE20 -> 8.89 | H17: ='Idle-Normal'!AF20 -> ba | I17: =G17*(VLOOKUP(H17,tab_fatorTestes[],3,0)) -> 8.89e+93 | J17: =LEN(TEXT(I17,0)) -> 94 | K17: {=_xlfn.XLOOKUP(J17,tab_fatorTestes[[#All],[Dgts]],tab_fatorTestes[[#All],[Fator]],"Erro",-1,1)} -> ba | L17: =K17=H17 -> TRUE | M17: =I17*$G$2 -> 5.2451e+94 | N17: =LEN(TEXT(M17,0)) -> 95 | O17: =VLOOKUP(R17,tab_fatorTestes[],3,0) -> 1e+93 | P17: =M17/O17 -> 52.451 | Q17: =ROUND(P17,(IF(P17<10,2,IF(P17<100,1,IF(P17>100,0))))) -> 52.5 | R17: {=_xlfn.XLOOKUP(N17,tab_fatorTestes[[#All],[Dgts]],tab_fatorTestes[[#All],[Fator]],"Erro",-1,1)} -> ba
A18: al | B18: =B17+1 -> 17 | C18: =C17*1000 -> 1e+48 | D18: =LEN(TEXT(C18,0)) -> 49 | F18: Jade | G18: ='Idle-Normal'!AE21 -> 15.1 | H18: ='Idle-Normal'!AF21 -> ba | I18: =G18*(VLOOKUP(H18,tab_fatorTestes[],3,0)) -> 1.51e+94 | J18: =LEN(TEXT(I18,0)) -> 95 | K18: {=_xlfn.XLOOKUP(J18,tab_fatorTestes[[#All],[Dgts]],tab_fatorTestes[[#All],[Fator]],"Erro",-1,1)} -> ba | L18: =K18=H18 -> TRUE | M18: =I18*$G$2 -> 8.909e+94 | N18: =LEN(TEXT(M18,0)) -> 95 | O18: =VLOOKUP(R18,tab_fatorTestes[],3,0) -> 1e+93 | P18: =M18/O18 -> 89.09 | Q18: =ROUND(P18,(IF(P18<10,2,IF(P18<100,1,IF(P18>100,0))))) -> 89.1 | R18: {=_xlfn.XLOOKUP(N18,tab_fatorTestes[[#All],[Dgts]],tab_fatorTestes[[#All],[Fator]],"Erro",-1,1)} -> ba
A19: am | B19: =B18+1 -> 18 | C19: =C18*1000 -> 1e+51 | D19: =LEN(TEXT(C19,0)) -> 52 | F19: Total | M19: =SUM(M14:M18) -> 1.622854e+95 | N19: =LEN(TEXT(M19,0)) -> 96 | O19: =VLOOKUP(R19,tab_fatorTestes[],3,0) -> 1e+93 | P19: =M19/O19 -> 162.2854 | Q19: =ROUND(P19,(IF(P19<10,2,IF(P19<100,1,IF(P19>100,0))))) -> 162 | R19: {=_xlfn.XLOOKUP(N19,tab_fatorTestes[[#All],[Dgts]],tab_fatorTestes[[#All],[Fator]],"Erro",-1,1)} -> ba
A20: an | B20: =B19+1 -> 19 | C20: =C19*1000 -> 1e+54 | D20: =LEN(TEXT(C20,0)) -> 55
A21: ao | B21: =B20+1 -> 20 | C21: =C20*1000 -> 1e+57 | D21: =LEN(TEXT(C21,0)) -> 58 | F21: Ambar | G21: ='Idle-Normal'!AE27 -> 401 | H21: ='Idle-Normal'!AF27 -> ay | I21: =G21*(VLOOKUP(H21,tab_fatorTestes[],3,0)) -> 4.01e+89 | J21: =LEN(TEXT(I21,0)) -> 90 | K21: {=_xlfn.XLOOKUP(J21,tab_fatorTestes[[#All],[Dgts]],tab_fatorTestes[[#All],[Fator]],"Erro",-1,1)} -> ay | L21: =K21=H21 -> TRUE | M21: =I21*$G$2 -> 2.3659e+90 | N21: =LEN(TEXT(M21,0)) -> 91 | O21: =VLOOKUP(R21,tab_fatorTestes[],3,0) -> 1e+90 | P21: =M21/O21 -> 2.3659 | Q21: =ROUND(P21,(IF(P21<10,2,IF(P21<100,1,IF(P21>100,0))))) -> 2.37 | R21: {=_xlfn.XLOOKUP(N21,tab_fatorTestes[[#All],[Dgts]],tab_fatorTestes[[#All],[Fator]],"Erro",-1,1)} -> az
A22: ap | B22: =B21+1 -> 21 | C22: =C21*1000 -> 1e+60 | D22: =LEN(TEXT(C22,0)) -> 61 | F22: Pedra do Sol | G22: ='Idle-Normal'!AE28 -> 1.72 | H22: ='Idle-Normal'!AF28 -> az | I22: =G22*(VLOOKUP(H22,tab_fatorTestes[],3,0)) -> 1.72e+90 | J22: =LEN(TEXT(I22,0)) -> 91 | K22: {=_xlfn.XLOOKUP(J22,tab_fatorTestes[[#All],[Dgts]],tab_fatorTestes[[#All],[Fator]],"Erro",-1,1)} -> az | L22: =K22=H22 -> TRUE | M22: =I22*$G$2 -> 1.0148e+91 | N22: =LEN(TEXT(M22,0)) -> 92 | O22: =VLOOKUP(R22,tab_fatorTestes[],3,0) -> 1e+90 | P22: =M22/O22 -> 10.148 | Q22: =ROUND(P22,(IF(P22<10,2,IF(P22<100,1,IF(P22>100,0))))) -> 10.1 | R22: {=_xlfn.XLOOKUP(N22,tab_fatorTestes[[#All],[Dgts]],tab_fatorTestes[[#All],[Fator]],"Erro",-1,1)} -> az
A23: aq | B23: =B22+1 -> 22 | C23: =C22*1000 -> 1e+63 | D23: =LEN(TEXT(C23,0)) -> 64 | F23: Topázio | G23: ='Idle-Normal'!AE29 -> 1.95 | H23: ='Idle-Normal'!AF29 -> az | I23: =G23*(VLOOKUP(H23,tab_fatorTestes[],3,0)) -> 1.95e+90 | J23: =LEN(TEXT(I23,0)) -> 91 | K23: {=_xlfn.XLOOKUP(J23,tab_fatorTestes[[#All],[Dgts]],tab_fatorTestes[[#All],[Fator]],"Erro",-1,1)} -> az | L23: =K23=H23 -> TRUE | M23: =I23*$G$2 -> 1.1505e+91 | N23: =LEN(TEXT(M23,0)) -> 92 | O23: =VLOOKUP(R23,tab_fatorTestes[],3,0) -> 1e+90 | P23: =M23/O23 -> 11.505 | Q23: =ROUND(P23,(IF(P23<10,2,IF(P23<100,1,IF(P23>100,0))))) -> 11.5 | R23: {=_xlfn.XLOOKUP(N23,tab_fatorTestes[[#All],[Dgts]],tab_fatorTestes[[#All],[Fator]],"Erro",-1,1)} -> az
A24: ar | B24: =B23+1 -> 23 | C24: =C23*1000 -> 1e+66 | D24: =LEN(TEXT(C24,0)) -> 67 | F24: Platina | G24: ='Idle-Normal'!AE30 -> 6.32 | H24: ='Idle-Normal'!AF30 -> az | I24: =G24*(VLOOKUP(H24,tab_fatorTestes[],3,0)) -> 6.32e+90 | J24: =LEN(TEXT(I24,0)) -> 91 | K24: {=_xlfn.XLOOKUP(J24,tab_fatorTestes[[#All],[Dgts]],tab_fatorTestes[[#All],[Fator]],"Erro",-1,1)} -> az | L24: =K24=H24 -> TRUE | M24: =I24*$G$2 -> 3.7288e+91 | N24: =LEN(TEXT(M24,0)) -> 92 | O24: =VLOOKUP(R24,tab_fatorTestes[],3,0) -> 1e+90 | P24: =M24/O24 -> 37.288 | Q24: =ROUND(P24,(IF(P24<10,2,IF(P24<100,1,IF(P24>100,0))))) -> 37.3 | R24: {=_xlfn.XLOOKUP(N24,tab_fatorTestes[[#All],[Dgts]],tab_fatorTestes[[#All],[Fator]],"Erro",-1,1)} -> az
A25: as | B25: =B24+1 -> 24 | C25: =C24*1000 -> 1e+69 | D25: =LEN(TEXT(C25,0)) -> 70 | F25: Obsidiana | G25: ='Idle-Normal'!AE31 -> 11.1 | H25: ='Idle-Normal'!AF31 -> az | I25: =G25*(VLOOKUP(H25,tab_fatorTestes[],3,0)) -> 1.11e+91 | J25: =LEN(TEXT(I25,0)) -> 92 | K25: {=_xlfn.XLOOKUP(J25,tab_fatorTestes[[#All],[Dgts]],tab_fatorTestes[[#All],[Fator]],"Erro",-1,1)} -> az | L25: =K25=H25 -> TRUE | M25: =I25*$G$2 -> 6.549e+91 | N25: =LEN(TEXT(M25,0)) -> 92 | O25: =VLOOKUP(R25,tab_fatorTestes[],3,0) -> 1e+90 | P25: =M25/O25 -> 65.49 | Q25: =ROUND(P25,(IF(P25<10,2,IF(P25<100,1,IF(P25>100,0))))) -> 65.5 | R25: {=_xlfn.XLOOKUP(N25,tab_fatorTestes[[#All],[Dgts]],tab_fatorTestes[[#All],[Fator]],"Erro",-1,1)} -> az
A26: at | B26: =B25+1 -> 25 | C26: =C25*1000 -> 1e+72 | D26: =LEN(TEXT(C26,0)) -> 73 | F26: Total | M26: =SUM(M21:M25) -> 1.267969e+92 | N26: =LEN(TEXT(M26,0)) -> 93 | O26: =VLOOKUP(R26,tab_fatorTestes[],3,0) -> 1e+90 | P26: =M26/O26 -> 126.7969 | Q26: =ROUND(P26,(IF(P26<10,2,IF(P26<100,1,IF(P26>100,0))))) -> 127 | R26: {=_xlfn.XLOOKUP(N26,tab_fatorTestes[[#All],[Dgts]],tab_fatorTestes[[#All],[Fator]],"Erro",-1,1)} -> az
A27: au | B27: =B26+1 -> 26 | C27: =C26*1000 -> 1e+75 | D27: =LEN(TEXT(C27,0)) -> 76
A28: av | B28: =B27+1 -> 27 | C28: =C27*1000 -> 1e+78 | D28: =LEN(TEXT(C28,0)) -> 79 | F28: Heliodoro | G28: ='Idle-Normal'!AE37 -> 1.03 | H28: ='Idle-Normal'!AF37 -> aw | I28: =G28*(VLOOKUP(H28,tab_fatorTestes[],3,0)) -> 1.03e+81 | J28: =LEN(TEXT(I28,0)) -> 82 | K28: {=_xlfn.XLOOKUP(J28,tab_fatorTestes[[#All],[Dgts]],tab_fatorTestes[[#All],[Fator]],"Erro",-1,1)} -> aw | L28: =K28=H28 -> TRUE | M28: =I28*$G$2 -> 6.077e+81 | N28: =LEN(TEXT(M28,0)) -> 82 | O28: =VLOOKUP(R28,tab_fatorTestes[],3,0) -> 1e+81 | P28: =M28/O28 -> 6.077 | Q28: =ROUND(P28,(IF(P28<10,2,IF(P28<100,1,IF(P28>100,0))))) -> 6.08 | R28: {=_xlfn.XLOOKUP(N28,tab_fatorTestes[[#All],[Dgts]],tab_fatorTestes[[#All],[Fator]],"Erro",-1,1)} -> aw
A29: aw | B29: =B28+1 -> 28 | C29: =C28*1000 -> 1e+81 | D29: =LEN(TEXT(C29,0)) -> 82 | F29: Realgar | G29: ='Idle-Normal'!AE38 -> 31.9 | H29: ='Idle-Normal'!AF38 -> av | I29: =G29*(VLOOKUP(H29,tab_fatorTestes[],3,0)) -> 3.19e+79 | J29: =LEN(TEXT(I29,0)) -> 80 | K29: {=_xlfn.XLOOKUP(J29,tab_fatorTestes[[#All],[Dgts]],tab_fatorTestes[[#All],[Fator]],"Erro",-1,1)} -> av | L29: =K29=H29 -> TRUE | M29: =I29*$G$2 -> 1.8821e+80 | N29: =LEN(TEXT(M29,0)) -> 81 | O29: =VLOOKUP(R29,tab_fatorTestes[],3,0) -> 1e+78 | P29: =M29/O29 -> 188.21 | Q29: =ROUND(P29,(IF(P29<10,2,IF(P29<100,1,IF(P29>100,0))))) -> 188 | R29: {=_xlfn.XLOOKUP(N29,tab_fatorTestes[[#All],[Dgts]],tab_fatorTestes[[#All],[Fator]],"Erro",-1,1)} -> av
A30: ax | B30: =B29+1 -> 29 | C30: =C29*1000 -> 1e+84 | D30: =LEN(TEXT(C30,0)) -> 85 | F30: Alexandrita | G30: ='Idle-Normal'!AE39 -> 282 | H30: ='Idle-Normal'!AF39 -> av | I30: =G30*(VLOOKUP(H30,tab_fatorTestes[],3,0)) -> 2.82e+80 | J30: =LEN(TEXT(I30,0)) -> 81 | K30: {=_xlfn.XLOOKUP(J30,tab_fatorTestes[[#All],[Dgts]],tab_fatorTestes[[#All],[Fator]],"Erro",-1,1)} -> av | L30: =K30=H30 -> TRUE | M30: =I30*$G$2 -> 1.6638e+81 | N30: =LEN(TEXT(M30,0)) -> 82 | O30: =VLOOKUP(R30,tab_fatorTestes[],3,0) -> 1e+81 | P30: =M30/O30 -> 1.6638 | Q30: =ROUND(P30,(IF(P30<10,2,IF(P30<100,1,IF(P30>100,0))))) -> 1.66 | R30: {=_xlfn.XLOOKUP(N30,tab_fatorTestes[[#All],[Dgts]],tab_fatorTestes[[#All],[Fator]],"Erro",-1,1)} -> aw
A31: ay | B31: =B30+1 -> 30 | C31: =C30*1000 -> 1e+87 | D31: =LEN(TEXT(C31,0)) -> 88 | F31: Celestina | G31: ='Idle-Normal'!AE40 -> 44.6 | H31: ='Idle-Normal'!AF40 -> av | I31: =G31*(VLOOKUP(H31,tab_fatorTestes[],3,0)) -> 4.46e+79 | J31: =LEN(TEXT(I31,0)) -> 80 | K31: {=_xlfn.XLOOKUP(J31,tab_fatorTestes[[#All],[Dgts]],tab_fatorTestes[[#All],[Fator]],"Erro",-1,1)} -> av | L31: =K31=H31 -> TRUE | M31: =I31*$G$2 -> 2.6314e+80 | N31: =LEN(TEXT(M31,0)) -> 81 | O31: =VLOOKUP(R31,tab_fatorTestes[],3,0) -> 1e+78 | P31: =M31/O31 -> 263.14 | Q31: =ROUND(P31,(IF(P31<10,2,IF(P31<100,1,IF(P31>100,0))))) -> 263 | R31: {=_xlfn.XLOOKUP(N31,tab_fatorTestes[[#All],[Dgts]],tab_fatorTestes[[#All],[Fator]],"Erro",-1,1)} -> av
A32: az | B32: =B31+1 -> 31 | C32: =C31*1000 -> 1e+90 | D32: =LEN(TEXT(C32,0)) -> 91 | F32: Titanita | G32: ='Idle-Normal'!AE41 -> 1.02 | H32: ='Idle-Normal'!AF41 -> aw | I32: =G32*(VLOOKUP(H32,tab_fatorTestes[],3,0)) -> 1.02e+81 | J32: =LEN(TEXT(I32,0)) -> 82 | K32: {=_xlfn.XLOOKUP(J32,tab_fatorTestes[[#All],[Dgts]],tab_fatorTestes[[#All],[Fator]],"Erro",-1,1)} -> aw | L32: =K32=H32 -> TRUE | M32: =I32*$G$2 -> 6.018e+81 | N32: =LEN(TEXT(M32,0)) -> 82 | O32: =VLOOKUP(R32,tab_fatorTestes[],3,0) -> 1e+81 | P32: =M32/O32 -> 6.018 | Q32: =ROUND(P32,(IF(P32<10,2,IF(P32<100,1,IF(P32>100,0))))) -> 6.02 | R32: {=_xlfn.XLOOKUP(N32,tab_fatorTestes[[#All],[Dgts]],tab_fatorTestes[[#All],[Fator]],"Erro",-1,1)} -> aw
A33: ba | B33: =B32+1 -> 32 | C33: =C32*1000 -> 1e+93 | D33: =LEN(TEXT(C33,0)) -> 94 | F33: Total | M33: =SUM(M28:M32) -> 1.421015e+82 | N33: =LEN(TEXT(M33,0)) -> 83 | O33: =VLOOKUP(R33,tab_fatorTestes[],3,0) -> 1e+81 | P33: =M33/O33 -> 14.21015 | Q33: =ROUND(P33,(IF(P33<10,2,IF(P33<100,1,IF(P33>100,0))))) -> 14.2 | R33: {=_xlfn.XLOOKUP(N33,tab_fatorTestes[[#All],[Dgts]],tab_fatorTestes[[#All],[Fator]],"Erro",-1,1)} -> aw
A34: bb | B34: =B33+1 -> 33 | C34: =C33*1000 -> 1e+96 | D34: =LEN(TEXT(C34,0)) -> 97
A35: bc | B35: =B34+1 -> 34 | C35: =C34*1000 -> 1e+99 | D35: =LEN(TEXT(C35,0)) -> 100 | F35: Fluorita | G35: ='Idle-Normal'!AE47 -> 1.63 | H35: ='Idle-Normal'!AF47 -> au | I35: =G35*(VLOOKUP(H35,tab_fatorTestes[],3,0)) -> 1.63e+75 | J35: =LEN(TEXT(I35,0)) -> 76 | K35: {=_xlfn.XLOOKUP(J35,tab_fatorTestes[[#All],[Dgts]],tab_fatorTestes[[#All],[Fator]],"Erro",-1,1)} -> au | L35: =K35=H35 -> TRUE | M35: =I35*$G$2 -> 9.617e+75 | N35: =LEN(TEXT(M35,0)) -> 76 | O35: =VLOOKUP(R35,tab_fatorTestes[],3,0) -> 1e+75 | P35: =M35/O35 -> 9.617 | Q35: =ROUND(P35,(IF(P35<10,2,IF(P35<100,1,IF(P35>100,0))))) -> 9.62 | R35: {=_xlfn.XLOOKUP(N35,tab_fatorTestes[[#All],[Dgts]],tab_fatorTestes[[#All],[Fator]],"Erro",-1,1)} -> au
A36: bd | B36: =B35+1 -> 35 | C36: =C35*1000 -> 1e+102 | D36: =LEN(TEXT(C36,0)) -> 103 | F36: Quartzo | G36: ='Idle-Normal'!AE48 -> 6.63 | H36: ='Idle-Normal'!AF48 -> au | I36: =G36*(VLOOKUP(H36,tab_fatorTestes[],3,0)) -> 6.63e+75 | J36: =LEN(TEXT(I36,0)) -> 76 | K36: {=_xlfn.XLOOKUP(J36,tab_fatorTestes[[#All],[Dgts]],tab_fatorTestes[[#All],[Fator]],"Erro",-1,1)} -> au | L36: =K36=H36 -> TRUE | M36: =I36*$G$2 -> 3.9117e+76 | N36: =LEN(TEXT(M36,0)) -> 77 | O36: =VLOOKUP(R36,tab_fatorTestes[],3,0) -> 1e+75 | P36: =M36/O36 -> 39.117 | Q36: =ROUND(P36,(IF(P36<10,2,IF(P36<100,1,IF(P36>100,0))))) -> 39.1 | R36: {=_xlfn.XLOOKUP(N36,tab_fatorTestes[[#All],[Dgts]],tab_fatorTestes[[#All],[Fator]],"Erro",-1,1)} -> au
A37: be | B37: =B36+1 -> 36 | C37: =C36*1000 -> 1e+105 | D37: =LEN(TEXT(C37,0)) -> 106 | F37: Argonita | G37: ='Idle-Normal'!AE49 -> 113 | H37: ='Idle-Normal'!AF49 -> au | I37: =G37*(VLOOKUP(H37,tab_fatorTestes[],3,0)) -> 1.13e+77 | J37: =LEN(TEXT(I37,0)) -> 78 | K37: {=_xlfn.XLOOKUP(J37,tab_fatorTestes[[#All],[Dgts]],tab_fatorTestes[[#All],[Fator]],"Erro",-1,1)} -> au | L37: =K37=H37 -> TRUE | M37: =I37*$G$2 -> 6.667e+77 | N37: =LEN(TEXT(M37,0)) -> 78 | O37: =VLOOKUP(R37,tab_fatorTestes[],3,0) -> 1e+75 | P37: =M37/O37 -> 666.7 | Q37: =ROUND(P37,(IF(P37<10,2,IF(P37<100,1,IF(P37>100,0))))) -> 667 | R37: {=_xlfn.XLOOKUP(N37,tab_fatorTestes[[#All],[Dgts]],tab_fatorTestes[[#All],[Fator]],"Erro",-1,1)} -> au
A38: bf | B38: =B37+1 -> 37 | C38: =C37*1000 -> 1e+108 | D38: =LEN(TEXT(C38,0)) -> 109 | F38: Berilo | G38: ='Idle-Normal'!AE50 -> 151 | H38: ='Idle-Normal'!AF50 -> au | I38: =G38*(VLOOKUP(H38,tab_fatorTestes[],3,0)) -> 1.51e+77 | J38: =LEN(TEXT(I38,0)) -> 78 | K38: {=_xlfn.XLOOKUP(J38,tab_fatorTestes[[#All],[Dgts]],tab_fatorTestes[[#All],[Fator]],"Erro",-1,1)} -> au | L38: =K38=H38 -> TRUE | M38: =I38*$G$2 -> 8.909e+77 | N38: =LEN(TEXT(M38,0)) -> 78 | O38: =VLOOKUP(R38,tab_fatorTestes[],3,0) -> 1e+75 | P38: =M38/O38 -> 890.9 | Q38: =ROUND(P38,(IF(P38<10,2,IF(P38<100,1,IF(P38>100,0))))) -> 891 | R38: {=_xlfn.XLOOKUP(N38,tab_fatorTestes[[#All],[Dgts]],tab_fatorTestes[[#All],[Fator]],"Erro",-1,1)} -> au
A39: bg | B39: =B38+1 -> 38 | C39: =C38*1000 -> 1e+111 | D39: =LEN(TEXT(C39,0)) -> 112 | F39: Calcita | G39: ='Idle-Normal'!AE51 -> 102 | H39: ='Idle-Normal'!AF51 -> au | I39: =G39*(VLOOKUP(H39,tab_fatorTestes[],3,0)) -> 1.02e+77 | J39: =LEN(TEXT(I39,0)) -> 78 | K39: {=_xlfn.XLOOKUP(J39,tab_fatorTestes[[#All],[Dgts]],tab_fatorTestes[[#All],[Fator]],"Erro",-1,1)} -> au | L39: =K39=H39 -> TRUE | M39: =I39*$G$2 -> 6.018e+77 | N39: =LEN(TEXT(M39,0)) -> 78 | O39: =VLOOKUP(R39,tab_fatorTestes[],3,0) -> 1e+75 | P39: =M39/O39 -> 601.8 | Q39: =ROUND(P39,(IF(P39<10,2,IF(P39<100,1,IF(P39>100,0))))) -> 602 | R39: {=_xlfn.XLOOKUP(N39,tab_fatorTestes[[#All],[Dgts]],tab_fatorTestes[[#All],[Fator]],"Erro",-1,1)} -> au
A40: bh | B40: =B39+1 -> 39 | C40: =C39*1000 -> 1e+114 | D40: =LEN(TEXT(C40,0)) -> 115 | F40: Total | M40: =SUM(M35:M39) -> 2.208134e+78 | N40: =LEN(TEXT(M40,0)) -> 79 | O40: =VLOOKUP(R40,tab_fatorTestes[],3,0) -> 1e+78 | P40: =M40/O40 -> 2.208134 | Q40: =ROUND(P40,(IF(P40<10,2,IF(P40<100,1,IF(P40>100,0))))) -> 2.21 | R40: {=_xlfn.XLOOKUP(N40,tab_fatorTestes[[#All],[Dgts]],tab_fatorTestes[[#All],[Fator]],"Erro",-1,1)} -> av
...

Sheet Planilha1
H9: 80 | I9: =SUM(H10:H17) -> 78
G10: Pé | H10: 5
G11: Piso | H11: 2
G12: Espaço | H12: 32
G13: piso2 | H13: 2
G14: Espaço 2 | H14: 32
G15: Teto | H15: 5
